Workbook

Sheet Du lieu
A1: NĂM | B1: 2026
A2: Kế hoạch hiệu chỉnh Hợp đồng
D3: ITO | G3: UNI | J3: BIZ | M3: G2B
A4: Tháng | B4: Có cộng dồn | D4: KH hiệu chỉnh | E4: Thực tế | G4: KH hiệu chỉnh | H4: Thực tế | J4: KH hiệu chỉnh | K4: Thực tế | M4: KH hiệu chỉnh | N4: Thực tế
A5: 1 | B5: X | D5: =#ref! -> #NAME? | E5: =#ref! -> #NAME? | G5: =#ref! -> #NAME? | H5: =#ref! -> #NAME? | J5: =#ref! -> #NAME? | K5: =#ref! -> #NAME? | M5: =#ref! -> #NAME? | N5: =#ref! -> #NAME?
A6: 2 | B6: =IF(YEAR(TODAY())=$B$1, IF(A6<MONTH(TODAY()), "","X"), IF(A6<>12, "","X")) | D6: =#ref! -> #NAME? | E6: =#ref! -> #NAME? | G6: =#ref! -> #NAME? | H6: =#ref! -> #NAME? | J6: =#ref! -> #NAME? | K6: =#ref! -> #NAME? | M6: =#ref! -> #NAME? | N6: =#ref! -> #NAME?
A7: 3 | B7: =IF(YEAR(TODAY())=$B$1, IF(A7<MONTH(TODAY()), "","X"), IF(A7<>12, "","X")) | D7: =#ref! -> #NAME? | E7: =#ref! -> #NAME? | G7: =#ref! -> #NAME? | H7: =#ref! -> #NAME? | J7: =#ref! -> #NAME? | K7: =#ref! -> #NAME? | M7: =#ref! -> #NAME? | N7: =#ref! -> #NAME?
A8: 4 | B8: =IF(YEAR(TODAY())=$B$1, IF(A8<MONTH(TODAY()), "","X"), IF(A8<>12, "","X")) | D8: =#ref! -> #NAME? | E8: =#ref! -> #NAME? | G8: =#ref! -> #NAME? | H8: =#ref! -> #NAME? | J8: =#ref! -> #NAME? | K8: =#ref! -> #NAME? | M8: =#ref! -> #NAME? | N8: =#ref! -> #NAME?
A9: 5 | B9: =IF(YEAR(TODAY())=$B$1, IF(A9<MONTH(TODAY()), "","X"), IF(A9<>12, "","X")) | D9: =#ref! -> #NAME? | E9: =#ref! -> #NAME? | G9: =#ref! -> #NAME? | H9: =#ref! -> #NAME? | J9: =#ref! -> #NAME? | K9: =#ref! -> #NAME? | M9: =#ref! -> #NAME? | N9: =#ref! -> #NAME?
A10: 6 | B10: =IF(YEAR(TODAY())=$B$1, IF(A10<MONTH(TODAY()), "","X"), IF(A10<>12, "","X")) | D10: =#ref! -> #NAME? | E10: =#ref! -> #NAME? | G10: =#ref! -> #NAME? | H10: =#ref! -> #NAME? | J10: =#ref! -> #NAME? | K10: =#ref! -> #NAME? | M10: =#ref! -> #NAME? | N10: =#ref! -> #NAME?
A11: 7 | B11: =IF(YEAR(TODAY())=$B$1, IF(A11<MONTH(TODAY()), "","X"), IF(A11<>12, "","X")) | D11: =#ref! -> #NAME? | E11: =#ref! -> #NAME? | G11: =#ref! -> #NAME? | H11: =#ref! -> #NAME? | J11: =#ref! -> #NAME? | K11: =#ref! -> #NAME? | M11: =#ref! -> #NAME? | N11: =#ref! -> #NAME?
A12: 8 | B12: =IF(YEAR(TODAY())=$B$1, IF(A12<MONTH(TODAY()), "","X"), IF(A12<>12, "","X")) | D12: =#ref! -> #NAME? | E12: =#ref! -> #NAME? | G12: =#ref! -> #NAME? | H12: =#ref! -> #NAME? | J12: =#ref! -> #NAME? | K12: =#ref! -> #NAME? | M12: =#ref! -> #NAME? | N12: =#ref! -> #NAME?
A13: 9 | B13: =IF(YEAR(TODAY())=$B$1, IF(A13<MONTH(TODAY()), "","X"), IF(A13<>12, "","X")) -> X | D13: =#ref! -> #NAME? | E13: =#ref! -> #NAME? | G13: =#ref! -> #NAME? | H13: =#ref! -> #NAME? | J13: =#ref! -> #NAME? | K13: =#ref! -> #NAME? | M13: =#ref! -> #NAME? | N13: =#ref! -> #NAME?
A14: 10 | B14: =IF(YEAR(TODAY())=$B$1, IF(A14<MONTH(TODAY()), "","X"), IF(A14<>12, "","X")) -> X | D14: =#ref! -> #NAME? | E14: =#ref! -> #NAME? | G14: =#ref! -> #NAME? | H14: =#ref! -> #NAME? | J14: =#ref! -> #NAME? | K14: =#ref! -> #NAME? | M14: =#ref! -> #NAME? | N14: =#ref! -> #NAME?
A15: 11 | B15: =IF(YEAR(TODAY())=$B$1, IF(A15<MONTH(TODAY()), "","X"), IF(A15<>12, "","X")) -> X | D15: =#ref! -> #NAME? | E15: =#ref! -> #NAME? | G15: =#ref! -> #NAME? | H15: =#ref! -> #NAME? | J15: =#ref! -> #NAME? | K15: =#ref! -> #NAME? | M15: =#ref! -> #NAME? | N15: =#ref! -> #NAME?
A16: 12 | B16: =IF(YEAR(TODAY())=$B$1, IF(A16<MONTH(TODAY()), "","X"), IF(A16<>12, "","X")) -> X | D16: =#ref! -> #NAME? | E16: =#ref! -> #NAME? | G16: =#ref! -> #NAME? | H16: =#ref! -> #NAME? | J16: =#ref! -> #NAME? | K16: =#ref! -> #NAME? | M16: =#ref! -> #NAME? | N16: =#ref! -> #NAME?
A17: Năm | D17: =SUMIF($B$5:$B$16, "X", D5:D16) -> #NAME? | E17: =SUMIF($B$5:$B$16, "", E5:E16) -> #NAME? | G17: =SUMIF($B$5:$B$16, "X", G5:G16) -> #NAME? | H17: =SUMIF($B$5:$B$16, "", H5:H16) -> #NAME? | J17: =SUMIF($B$5:$B$16, "X", J5:J16) -> #NAME? | K17: =SUMIF($B$5:$B$16, "", K5:K16) -> #NAME? | M17: =SUMIF($B$5:$B$16, "X", M5:M16) -> #NAME? | N17: =SUMIF($B$5:$B$16, "", N5:N16) -> #NAME?
A19: Kế hoạch hiệu chỉnh Doanh thu
D20: ITO | G20: UNI | J20: BIZ | M20: G2B
A21: Tháng | B21: Có cộng dồn | D21: KH hiệu chỉnh | E21: Thực tế | G21: KH hiệu chỉnh | H21: Thực tế | J21: KH hiệu chỉnh | K21: Thực tế | M21: KH hiệu chỉnh | N21: Thực tế
A22: 1 | B22: X | D22: =#ref! -> #NAME? | E22: =#ref! -> #NAME? | G22: =#ref! -> #NAME? | H22: =#ref! -> #NAME? | J22: =#ref! -> #NAME? | K22: =#ref! -> #NAME? | M22: =#ref! -> #NAME? | N22: =#ref! -> #NAME?
A23: 2 | B23: =IF(YEAR(TODAY())=$B$1, IF(A23<MONTH(TODAY()), "","X"), IF(A23<>12, "","X")) | D23: =#ref! -> #NAME? | E23: =#ref! -> #NAME? | G23: =#ref! -> #NAME? | H23: =#ref! -> #NAME? | J23: =#ref! -> #NAME? | K23: =#ref! -> #NAME? | M23: =#ref! -> #NAME? | N23: =#ref! -> #NAME?
A24: 3 | B24: =IF(YEAR(TODAY())=$B$1, IF(A24<MONTH(TODAY()), "","X"), IF(A24<>12, "","X")) | D24: =#ref! -> #NAME? | E24: =#ref! -> #NAME? | G24: =#ref! -> #NAME? | H24: =#ref! -> #NAME? | J24: =#ref! -> #NAME? | K24: =#ref! -> #NAME? | M24: =#ref! -> #NAME? | N24: =#ref! -> #NAME?
A25: 4 | B25: =IF(YEAR(TODAY())=$B$1, IF(A25<MONTH(TODAY()), "","X"), IF(A25<>12, "","X")) | D25: =#ref! -> #NAME? | E25: =#ref! -> #NAME? | G25: =#ref! -> #NAME? | H25: =#ref! -> #NAME? | J25: =#ref! -> #NAME? | K25: =#ref! -> #NAME? | M25: =#ref! -> #NAME? | N25: =#ref! -> #NAME?
A26: 5 | B26: =IF(YEAR(TODAY())=$B$1, IF(A26<MONTH(TODAY()), "","X"), IF(A26<>12, "","X")) | D26: =#ref! -> #NAME? | E26: =#ref! -> #NAME? | G26: =#ref! -> #NAME? | H26: =#ref! -> #NAME? | J26: =#ref! -> #NAME? | K26: =#ref! -> #NAME? | M26: =#ref! -> #NAME? | N26: =#ref! -> #NAME?
A27: 6 | B27: =IF(YEAR(TODAY())=$B$1, IF(A27<MONTH(TODAY()), "","X"), IF(A27<>12, "","X")) | D27: =#ref! -> #NAME? | E27: =#ref! -> #NAME? | G27: =#ref! -> #NAME? | H27: =#ref! -> #NAME? | J27: =#ref! -> #NAME? | K27: =#ref! -> #NAME? | M27: =#ref! -> #NAME? | N27: =#ref! -> #NAME?
A28: 7 | B28: =IF(YEAR(TODAY())=$B$1, IF(A28<MONTH(TODAY()), "","X"), IF(A28<>12, "","X")) | D28: =#ref! -> #NAME? | E28: =#ref! -> #NAME? | G28: =#ref! -> #NAME? | H28: =#ref! -> #NAME? | J28: =#ref! -> #NAME? | K28: =#ref! -> #NAME? | M28: =#ref! -> #NAME? | N28: =#ref! -> #NAME?
A29: 8 | B29: =IF(YEAR(TODAY())=$B$1, IF(A29<MONTH(TODAY()), "","X"), IF(A29<>12, "","X")) | D29: =#ref! -> #NAME? | E29: =#ref! -> #NAME? | G29: =#ref! -> #NAME? | H29: =#ref! -> #NAME? | J29: =#ref! -> #NAME? | K29: =#ref! -> #NAME? | M29: =#ref! -> #NAME? | N29: =#ref! -> #NAME?
A30: 9 | B30: =IF(YEAR(TODAY())=$B$1, IF(A30<MONTH(TODAY()), "","X"), IF(A30<>12, "","X")) -> X | D30: =#ref! -> #NAME? | E30: =#ref! -> #NAME? | G30: =#ref! -> #NAME? | H30: =#ref! -> #NAME? | J30: =#ref! -> #NAME? | K30: =#ref! -> #NAME? | M30: =#ref! -> #NAME? | N30: =#ref! -> #NAME?
A31: 10 | B31: =IF(YEAR(TODAY())=$B$1, IF(A31<MONTH(TODAY()), "","X"), IF(A31<>12, "","X")) -> X | D31: =#ref! -> #NAME? | E31: =#ref! -> #NAME? | G31: =#ref! -> #NAME? | H31: =#ref! -> #NAME? | J31: =#ref! -> #NAME? | K31: =#ref! -> #NAME? | M31: =#ref! -> #NAME? | N31: =#ref! -> #NAME?
A32: 11 | B32: =IF(YEAR(TODAY())=$B$1, IF(A32<MONTH(TODAY()), "","X"), IF(A32<>12, "","X")) -> X | D32: =#ref! -> #NAME? | E32: =#ref! -> #NAME? | G32: =#ref! -> #NAME? | H32: =#ref! -> #NAME? | J32: =#ref! -> #NAME? | K32: =#ref! -> #NAME? | M32: =#ref! -> #NAME? | N32: =#ref! -> #NAME?
A33: 12 | B33: =IF(YEAR(TODAY())=$B$1, IF(A33<MONTH(TODAY()), "","X"), IF(A33<>12, "","X")) -> X | D33: =#ref! -> #NAME? | E33: =#ref! -> #NAME? | G33: =#ref! -> #NAME? | H33: =#ref! -> #NAME? | J33: =#ref! -> #NAME? | K33: =#ref! -> #NAME? | M33: =#ref! -> #NAME? | N33: =#ref! -> #NAME?
A34: Năm | D34: =SUMIF($B$22:$B$33, "X", D22:D33) -> #NAME? | E34: =SUMIF($B$22:$B$33, "", E22:E33) -> #NAME? | G34: =SUMIF($B$22:$B$33, "X", G22:G33) -> #NAME? | H34: =SUMIF($B$22:$B$33, "", H22:H33) -> #NAME? | J34: =SUMIF($B$22:$B$33, "X", J22:J33) -> #NAME? | K34: =SUMIF($B$22:$B$33, "", K22:K33) -> #NAME? | M34: =SUMIF($B$22:$B$33, "X", M22:M33) -> #NAME? | N34: =SUMIF($B$22:$B$33, "", N22:N33) -> #NAME?
A36: Kế hoạch hiệu chỉnh Doanh thu từ HĐ mới
C38: UNI | G38: BIZ | K38: G2B
A39: Tháng | B39: Có cộng dồn | C39: KH hiệu chỉnh | D39: Thực tế | G39: KH hiệu chỉnh | H39: Thực tế | K39: KH hiệu chỉnh | L39: Thực tế
A40: 1 | B40: =IF(YEAR(TODAY())=$B$1, IF(A40<MONTH(TODAY()), "","X"), IF(A40<>12, "","X")) | C40: =#ref! -> #NAME? | D40: =#ref! -> #NAME? | G40: =#ref! -> #NAME? | H40: =#ref! -> #NAME? | K40: =#ref! -> #NAME? | L40: =#ref! -> #NAME?
A41: 2 | B41: =IF(YEAR(TODAY())=$B$1, IF(A41<MONTH(TODAY()), "","X"), IF(A41<>12, "","X")) | C41: =#ref! -> #NAME? | D41: =#ref! -> #NAME? | G41: =#ref! -> #NAME? | H41: =#ref! -> #NAME? | K41: =#ref! -> #NAME? | L41: =#ref! -> #NAME?
A42: 3 | B42: =IF(YEAR(TODAY())=$B$1, IF(A42<MONTH(TODAY()), "","X"), IF(A42<>12, "","X")) | C42: =#ref! -> #NAME? | D42: =#ref! -> #NAME? | G42: =#ref! -> #NAME? | H42: =#ref! -> #NAME? | K42: =#ref! -> #NAME? | L42: =#ref! -> #NAME?
A43: 4 | B43: =IF(YEAR(TODAY())=$B$1, IF(A43<MONTH(TODAY()), "","X"), IF(A43<>12, "","X")) | C43: =#ref! -> #NAME? | D43: =#ref! -> #NAME? | G43: =#ref! -> #NAME? | H43: =#ref! -> #NAME? | K43: =#ref! -> #NAME? | L43: =#ref! -> #NAME?
...

Sheet README
A1: HƯỚNG DẪN SỬ DỤNG
B3: MỤC TIÊU | C3: THAO TÁC SỬ DỤNG
A4: ĐẦU NĂM
A5: Thông số sử dụng | B5: - Định đúng thông số | C5: - Kiểm tra thời gian thiết đặt trên máy có đúng với thực tế
C6: - Sheet "Du lieu" (mặc định ẩn): đặt đúng năm tại ô B1
A7: Sheet "TH theo khach hang" | B7: - Lập kế hoạch doanh thu, hợp đồng cả năm theo khách hàng | C7: - Nhập từ cột A-F sheet
A8: Sheet "Ke hoach theo thang" | B8: - Lập kế hoạch chi tiết vào từng tháng của năm | C8: - Nhập từ cột J- AG. Nếu D&F khác 0, có nghĩa là chưa phân bổ đầy đủ vào tháng
C9: - Từ cột B-I là công thức: không nhập liệu, dùng để tham khảo và đối chiếu
C10: - Đối chiếu xong, có thể ẩn cột D-G
A11: HÀNG THÁNG
A12: Sheet "Thang xx" | B12: - Theo dõi doanh thu, hợp đồng từng tháng | C12: - Cột C, D, E, H là công thức: không nhập liệu
C13: - Cột F, I: mặc định theo kế hoạch đầu năm. Có thể nhập số liệu hiệu chỉnh theo tình hình hiện tại
C14: - Xác định cột J: Nếu doanh thu từ hợp đồng mới ký thì đánh dấu "x"
C15: - Cập nhật số liệu thực tế ở cột G, J và hiện trạng ở cột L
A16: QUẢN LÝ
A17: Sheet "Thuc te theo thang" | B17: - Tổng hợp số liệu thực tế doanh thu, hợp đồng chi tiết theo khách hàng trong 12 tháng | C17: - Tất cả các cột (trừ cột A) là công thức: không nhập liệu
A18: Sheet "Tong hop (TH)" | B18: - Tổng hợp số liệu doanh thu hợp đồng theo tháng, quý, năm | C18: - Tất cả các cột là công thức: không nhập liệu
B19: - Doanh thu, hợp đồng theo tháng, theo nhóm
B20: - Doanh thu theo tháng, theo nhóm phân biệt thu từ hợp đồng mới hay từ dự án
B21: - Doanh thu, hợp đồng theo quý theo nhóm
B22: - So sánh doanh thu, hợp đồng so với năm trước
A23: Sheet "KH hieu chinh theo thang" | B23: - Tổng hợp số liệu của KH hiệu chỉnh doanh thu, hợp đồng chi tiết theo khách hàng trong 12 tháng | C23: - Tất cả các cột (trừ cột A) là công thức: không nhập liệu
C24: - Nếu cột H không bằng cột I => có khả năng chưa lên KH hiệu chỉnh Doanh thu đầy đủ
A25: CUỐI NĂM
A26: Sheet "TH theo khach hang" | B26: - Báo cáo doanh thu, hợp đồng thực tế trong năm và doanh thu còn lại chuyển sang năm sau theo khách hàng. | C26: - Cột G, H, J là công thức: không nhập liệu
B27: - Cập nhật các thông tin ghi doanh thu từ Kế toán, các thông tin công nợ cần thu năm sau từ Thu hồi công nợ và thông tin khác | C27: - Nhập từ cột I, K, L sheet
A28: LƯU Ý KHI SỬ DỤNG
A29: Nếu phát sinh thêm khách hàng so với kế hoạch đầu năm (trong vòng 40 khách hàng của nhóm UNI, BIZ, GOV) | B29: - Nhập thông tin khách hàng duy nhất 1 lần ở sheet "TH theo khach hang" | C29: - Bước 1 - Sheet "TH theo khach hang": + Nhập cột A, B, C - Bước 2 - Các sheet "Thang xx" (từ tháng có phát sinh đến tháng 12): + Nhập theo đúng nguyên tắc của sheet này
A30: Sheet "Thang xx" | B30: - Cần tập trung vào khách hàng đang thực hiện | C30: - Sử dụng bộ lọc
B31: - Giá trị có hiệu chỉnh theo thời điểm hiện tại khác so với kế hoạch đầu năm | C31: - Nhập vào các cột "KH hiệu chỉnh"
B32: - Nếu giá trị tháng trước chưa thực hiện được cần chuyển sang tháng sau | C32: - "KH hiệu chỉnh" của tháng trước không cần xoá số liệu. Chuyển giá trị sang "KH hiệu chỉnh" của tháng sau, có thể hiệu chỉnh giá trị theo tính hình mới
A33: Nếu phát sinh hơn 40 khách hàng (nhóm UNI, BIZ, GOV) hoặc hơn 1 khách hàng (nhóm ITO): | B33: - Cập nhật dữ liệu từ sheet "TH theo khach hang" từ đó cập nhật mã số ở tất cả sheet có liên quan đến chi tiết khách hàng | C33: - Bước 1 - Sheet "TH theo khach hang": + Thêm dòng dữ liệu trước các dòng có tô màu + Tạo mã số mới theo thứ tự trong nhóm dự án + Copy công thức cho các dòng mới + Tuân thủ theo các nhập liệu của sheet này. + Nếu khách hàng phát sinh so với kế hoạch đầu năm: không nhập cột D, E, F
C34: - Bước 2 - Các sheet "Ke hoach theo thang", "Thuc te theo thang", "KH hieu chinh theo thang", các sheet "Thang xx" (từ tháng có phát sinh đến tháng 12): + Copy từ các dòng trước đó + Insert copied cells vào trước các dòng có tô màu + Kéo tạo mã phù hợp với sheet "TH theo khach hang" + Cập nhật thông tin phù hợp
A35: Thêm cột cho các sheet | B35: - Nếu có nhu cầu thêm cột để ghi nhận thêm thông tin | C35: - Thêm phía sau các cột đã định nghĩa
A36: Sheet "TH theo khach hang" | B36: - Thông tin công nợ (cột F): theo dõi chi tiết công nợ khách hàng cần thu trong năm sau | C36: - Có thể copy thông tin nào để Quản lý công nợ ở năm sau (nếu cần)
A37: Sheet "Du lieu" | B37: - Lưu dữ liệu trung gian để tính toán | C37: - Đầu năm cung cấp thông số "Năm". - Không nhập dữ liệu vào đây. Thường ở trạng thái Hide

Sheet BieuDo
A1: I. TỔNG HỢP SỐ LIỆU KINH DOANH - BPPM
A2: I.1. Kết quả đạt được | M2: II.2. Kết quả đạt được
M3: TT | N3: Hạng mục | O3: HỢP ĐỒNG | P3: DOANH THU
M4: 1 | N4: Thực tế | O4: =#ref! -> #NAME? | P4: =#ref! -> #NAME?
O5: =SUM(O6:O8) -> 0 | P5: =SUM(P6:P8) -> 0
N6: Nhóm ITO | O6: ='KH hieu chinh'!C58 -> 0 | P6: ='KH hieu chinh'!D58 -> 0
N7: Nhóm UNI | O7: ='KH hieu chinh'!C60 -> 0 | P7: ='KH hieu chinh'!D60 -> 0
N8: Nhón G2B | O8: ='KH hieu chinh'!C61 -> 0 | P8: ='KH hieu chinh'!D61 -> 0
M9: 2 | N9: KH dự kiến | O9: =SUM(O10:O12) -> 854990000 | P9: =SUM(P10:P12) -> 854990000
N10: Nhóm ITO | O10: ='KH hieu chinh'!C63 -> 0 | P10: ='KH hieu chinh'!D63 -> 0
N11: Nhóm UNI | O11: ='KH hieu chinh'!C64 -> 854990000 | P11: ='KH hieu chinh'!D64 -> 854990000
N12: Nhón G2B | O12: ='KH hieu chinh'!C65 -> 0 | P12: ='KH hieu chinh'!D65 -> 0
N13: Tổng năm (1+2) | O13: =O5+O9 -> 854990000 | P13: =P5+P9 -> 854990000
N14: Kế hoạch năm | O14: ='KH hieu chinh'!C67 -> 854990000 | P14: ='KH hieu chinh'!D67 -> 854990000
N15: Tỉ lệ | O15: =O13/O14 -> 1 | P15: =P13/P14 -> 1
A31: II. NHÓM ITO
A47: III.NHÓM UNI
A48: III.1. Kết quả đạt được
A80: III.2. Kế hoạch tiếp theo
A81: Dự kiến tổng giá trị hợp đồng: | C81: ='kh hieu chinh' #ref! -> #VALUE! | D81: đồng
O99: KẾ HOẠCH NĂM
O100: ='KH hieu chinh'!C25 -> 0
O103: DỰ KIẾN ĐẠT ĐƯỢC
O104: ='KH hieu chinh'!E25 -> 0
O107: HỢP ĐỒNG SO VỚI KẾ HOẠCH NĂM 2023
O110: ='KH hieu chinh'!E25/'KH hieu chinh'!C25 -> #DIV/0!
A115: Dự kiến tổng giá trị doanh thu: | C115: ='kh hieu chinh' #ref! -> #VALUE! | D115: đồng
O134: KẾ HOẠCH NĂM
O135: ='KH hieu chinh'!$F$25 -> 0
O138: DỰ KIẾN ĐẠT ĐƯỢC
O139: ='KH hieu chinh'!$H$25 -> 854990000
O142: DOANH THU SO VỚI KẾ HOẠCH NĂM 2023
O145: ='KH hieu chinh'!$H$25/'KH hieu chinh'!$F$25 -> #DIV/0!
A149: IV.NHÓM G2B
A150: IV.1. Kết quả đạt được
A181: IV.2. Kế hoạch tiếp theo
A182: Dự kiến tổng giá trị hợp đồng: | C182: ='KH hieu chinh'!$C$42 -> 0 | D182: đồng
O199: KẾ HOẠCH NĂM
O200: ='KH hieu chinh'!$C$51 -> 10000000000
O203: DỰ KIẾN ĐẠT ĐƯỢC
...

Sheet BieuDo_v2
A1: I. TỔNG HỢP SỐ LIỆU KINH DOANH - BPPM | E1: KH HỢP ĐỒNG: | G1: 30850000000 | I1: KH DOANH THU: | J1: 28900000000 | L1: GIÁ TRỊ ĐẠT ĐƯỢC SO VỚI KẾ HOẠCH NĂM
L2: TT | M2: HẠNG MỤC | N2: HỢP ĐỒNG | O2: DOANH THU
L3: 1 | M3: Thực tế (đạt) | N3: ='Tong hop (TH)'!N18 -> 0 | O3: ='Tong hop (TH)'!N50 -> 0
N4: =SUM(N5:N7) -> 0 | O4: =SUM(O5:O7) -> 0
M5: Nhóm ITO | N5: ='Tong hop (TH)'!E17 -> 0 | O5: ='Tong hop (TH)'!E49 -> 0
M6: Nhóm UNI | N6: ='Tong hop (TH)'!H17 -> 0 | O6: ='Tong hop (TH)'!H49 -> 0
M7: Nhón G2B | N7: ='Tong hop (TH)'!K17 -> 0 | O7: ='Tong hop (TH)'!K49 -> 0
L8: 2 | M8: Dự kiến (còn lại) | N8: =SUM(N9:N11) -> 854990000 | O8: =SUM(O9:O11) -> 854990000
M9: Nhóm ITO | N9: ='Tong hop (TH)'!D17 -> 0 | O9: ='Tong hop (TH)'!D49 -> 0
M10: Nhóm UNI | N10: ='Tong hop (TH)'!G17 -> 0 | O10: ='Tong hop (TH)'!G49 -> 0
M11: Nhón G2B | N11: ='Tong hop (TH)'!J17 -> 854990000 | O11: ='Tong hop (TH)'!J49 -> 854990000
M12: TỔNG CỘNG | N12: =N4+N8 -> 854990000 | O12: =O4+O8 -> 854990000
M13: KẾ HOẠCH NĂM | N13: ='Tong hop (TH)'!L17 -> 10800000000 | O13: ='Tong hop (TH)'!L49 -> 29800000000
M14: TỈ LỆ | N14: =N12/N13 -> 0.079165741 | O14: =O12/O13 -> 0.02869094
A17: II.NHÓM UNI
I19: KẾ HOẠCH HỢP ĐỒNG NĂM 2024
I20: ='KH hieu chinh'!C25 -> 0
I23: DỰ KIẾN ĐẠT HỢP ĐỒNG NĂM 2024
I24: ='KH hieu chinh'!E25 -> 0
I27: SO VỚI KẾ HOẠCH NĂM 2024
I28: =I24/I20 -> #DIV/0!
I33: KẾ HOẠCH DOANH THU NĂM 2024
I34: ='KH hieu chinh'!C51 -> 10000000000
I37: DỰ KIẾN ĐẠT DOANH THU NĂM 2024
I38: ='KH hieu chinh'!E51 -> 0
I41: SO VỚI KẾ HOẠCH NĂM 2024
I42: =I38/I34 -> 0
A46: III.NHÓM G2B
I48: KẾ HOẠCH NĂM
I49: ='KH hieu chinh'!F25 -> 0
I52: DỰ KIẾN ĐẠT ĐƯỢC
I53: ='KH hieu chinh'!H25 -> 854990000
I56: SO VỚI KẾ HOẠCH NĂM 2024
I57: =I53/I49 -> #DIV/0!
I61: KẾ HOẠCH NĂM
I62: ='KH hieu chinh'!F51 -> 9000000000
I65: DỰ KIẾN ĐẠT ĐƯỢC
I66: ='KH hieu chinh'!H51 -> 854990000
I69: SO VỚI KẾ HOẠCH NĂM 2024
I70: =I66/I62 -> 0.094998889
...

Sheet BC_Quy
D1: KH Hợp đồng: | E1: =#ref! -> #NAME? | G1: KH Doanh thu: | I1: =#ref! -> #NAME?
A2: I. TỔNG HỢP SỐ LIỆU KINH DOANH - BPPM | L2: GIÁ TRỊ ĐẠT ĐƯỢC SO VỚI KẾ HOẠCH
L3: TT | M3: Hạng mục | N3: HỢP ĐỒNG | O3: DOANH THU
L4: 1 | M4: Thực tế | N4: =#ref! -> #NAME? | O4: =#ref! -> #NAME?
N5: =SUM(N6:N8) -> 0 | O5: =SUM(O6:O8) -> 0
M6: Nhóm ITO | N6: ='KH hieu chinh'!C58 -> 0 | O6: ='KH hieu chinh'!D58 -> 0
M7: Nhóm UNI | N7: ='KH hieu chinh'!C60 -> 0 | O7: ='KH hieu chinh'!D60 -> 0
M8: Nhón G2B | N8: ='KH hieu chinh'!C61 -> 0 | O8: ='KH hieu chinh'!D61 -> 0
L9: 2 | M9: KH dự kiến | N9: =SUM(N10:N12) -> 854990000 | O9: =SUM(O10:O12) -> 854990000
M10: Nhóm ITO | N10: ='KH hieu chinh'!C63 -> 0 | O10: ='KH hieu chinh'!D63 -> 0
M11: Nhóm UNI | N11: ='KH hieu chinh'!C64 -> 854990000 | O11: ='KH hieu chinh'!D64 -> 854990000
M12: Nhón G2B | N12: ='KH hieu chinh'!C65 -> 0 | O12: ='KH hieu chinh'!D65 -> 0
M13: Tổng năm (1+2) | N13: =N5+N9 -> 854990000 | O13: =O5+O9 -> 854990000
M14: Kế hoạch năm | N14: ='KH hieu chinh'!C67 -> 854990000 | O14: ='KH hieu chinh'!D67 -> 854990000
M15: Tỉ lệ | N15: =N13/N14 -> 1 | O15: =O13/O14 -> 1
A18: II.QUÝ I: Báo cáo kết quả thực hiện Quý I và dự kiến kế hoạch thực hiện quý II
A19: II.1. Báo cáo kết quả thực hiện Quý I (1,2,3)
A55: III.NHÓM G2B
I57: KẾ HOẠCH NĂM
I58: ='KH hieu chinh'!$C$51 -> 10000000000
I61: DỰ KIẾN ĐẠT ĐƯỢC
I62: ='KH hieu chinh'!$E$51 -> 0
I65: SO VỚI KẾ HOẠCH NĂM 2024
I66: ='KH hieu chinh'!$E$51/'KH hieu chinh'!$C$51 -> 0
I70: KẾ HOẠCH NĂM
I71: ='KH hieu chinh'!$F$51 -> 9000000000
I74: DỰ KIẾN ĐẠT ĐƯỢC
I75: ='KH hieu chinh'!$H$51 -> 854990000
I78: SO VỚI KẾ HOẠCH NĂM 2024
I79: ='KH hieu chinh'!$H$51/'KH hieu chinh'!$F$51 -> 0.094998889
A83: IV. NHÓM ITO

Sheet Tong hop (TH)
A1: TỔNG HỢP THEO THÁNG
A2: HỢP ĐỒNG
A3: STT | B3: Tháng | C3: Nhóm ITO | F3: Nhóm UNI | I3: Nhóm G2B | L3: BPPM
C4: KH đầu năm | D4: KH hiệu chỉnh | E4: Thực tế | F4: KH đầu năm | G4: KH hiệu chỉnh | H4: Thực tế | I4: KH đầu năm | J4: KH hiệu chỉnh | K4: Thực tế | L4: KH đầu năm | M4: KH hiệu chỉnh | N4: Thực tế
A5: 1 | B5: Tháng 01 | C5: 900000000 | D5: ='KH hieu chinh'!M5 -> 0 | E5: ='Thuc te theo thang'!J5 -> 0 | G5: ='KH hieu chinh'!C5 -> 0 | H5: ='Thuc te theo thang'!J6 -> 0 | J5: ='KH hieu chinh'!D5 -> 0 | K5: ='Thuc te theo thang'!J208 -> 0 | L5: =C5+F5+I5 -> 900000000 | M5: =D5+G5+J5 -> 0 | N5: =E5+H5+K5 -> 0
A6: 2 | B6: Tháng 02 | C6: 900000000 | D6: ='KH hieu chinh'!M6 -> 0 | E6: ='Thuc te theo thang'!L5 -> 0 | G6: ='KH hieu chinh'!C6 -> 0 | H6: ='Thuc te theo thang'!L6 -> 0 | J6: ='KH hieu chinh'!D6 -> 0 | K6: ='Thuc te theo thang'!L208 -> 0 | L6: =C6+F6+I6 -> 900000000 | M6: =D6+G6+J6 -> 0 | N6: =E6+H6+K6 -> 0
A7: 3 | B7: Tháng 03 | C7: 900000000 | D7: ='KH hieu chinh'!M7 -> 0 | E7: ='Thuc te theo thang'!N5 -> 0 | G7: ='KH hieu chinh'!C7 -> 0 | H7: ='Thuc te theo thang'!N6 -> 0 | J7: ='KH hieu chinh'!D7 -> 0 | K7: ='Thuc te theo thang'!N208 -> 0 | L7: =C7+F7+I7 -> 900000000 | M7: =D7+G7+J7 -> 0 | N7: =E7+H7+K7 -> 0 | P7: =SUM(N5:N7) -> 0
A8: 4 | B8: Tháng 04 | C8: 900000000 | D8: ='KH hieu chinh'!M8 -> 0 | E8: ='Thuc te theo thang'!P5 -> 0 | G8: ='KH hieu chinh'!C8 -> 0 | H8: ='Thuc te theo thang'!P6 -> 0 | J8: ='KH hieu chinh'!D8 -> 0 | K8: ='Thuc te theo thang'!P208 -> 0 | L8: =C8+F8+I8 -> 900000000 | M8: =D8+G8+J8 -> 0 | N8: =E8+H8+K8 -> 0
A9: 5 | B9: Tháng 05 | C9: 900000000 | D9: ='KH hieu chinh'!M9 -> 0 | E9: ='Thuc te theo thang'!R5 -> 0 | G9: ='KH hieu chinh'!C9 -> 0 | H9: ='Thuc te theo thang'!R6 -> 0 | J9: ='KH hieu chinh'!D9 -> 0 | K9: ='Thuc te theo thang'!R208 -> 0 | L9: =C9+F9+I9 -> 900000000 | M9: =D9+G9+J9 -> 0 | N9: =E9+H9+K9 -> 0
A10: 6 | B10: Tháng 06 | C10: 900000000 | D10: ='KH hieu chinh'!M10 -> 0 | E10: ='Thuc te theo thang'!T5 -> 0 | G10: ='KH hieu chinh'!C10 -> 0 | H10: ='Thuc te theo thang'!T6 -> 0 | J10: ='KH hieu chinh'!D10 -> 0 | K10: ='Thuc te theo thang'!T208 -> 0 | L10: =C10+F10+I10 -> 900000000 | M10: =D10+G10+J10 -> 0 | N10: =E10+H10+K10 -> 0 | P10: =SUM(N8:N10) -> 0
A11: 7 | B11: Tháng 07 | C11: 900000000 | D11: ='KH hieu chinh'!M11 -> 0 | E11: ='Thuc te theo thang'!V5 -> 0 | G11: ='KH hieu chinh'!C11 -> 0 | H11: ='Thuc te theo thang'!V6 -> 0 | J11: ='KH hieu chinh'!D11 -> 0 | K11: ='Thuc te theo thang'!V208 -> 0 | L11: =C11+F11+I11 -> 900000000 | M11: =D11+G11+J11 -> 0 | N11: =E11+H11+K11 -> 0
A12: 8 | B12: Tháng 08 | C12: 900000000 | D12: ='KH hieu chinh'!M12 -> 0 | E12: ='Thuc te theo thang'!X5 -> 0 | G12: ='KH hieu chinh'!C12 -> 0 | H12: ='Thuc te theo thang'!X6 -> 0 | J12: ='KH hieu chinh'!D12 -> 0 | K12: ='Thuc te theo thang'!X208 -> 0 | L12: =C12+F12+I12 -> 900000000 | M12: =D12+G12+J12 -> 0 | N12: =E12+H12+K12 -> 0
A13: 9 | B13: Tháng 09 | C13: 900000000 | D13: ='KH hieu chinh'!M13 -> 0 | E13: ='Thuc te theo thang'!Z5 -> 0 | G13: ='KH hieu chinh'!C13 -> 0 | H13: ='Thuc te theo thang'!Z6 -> 0 | J13: ='KH hieu chinh'!D13 -> 0 | K13: ='Thuc te theo thang'!Z208 -> 0 | L13: =C13+F13+I13 -> 900000000 | M13: =D13+G13+J13 -> 0 | N13: =E13+H13+K13 -> 0 | P13: =SUM(N11:N13) -> 0
A14: 10 | B14: Tháng 10 | C14: 900000000 | D14: ='KH hieu chinh'!M14 -> 0 | E14: ='Thuc te theo thang'!AB5 -> 0 | G14: ='KH hieu chinh'!C14 -> 0 | H14: ='Thuc te theo thang'!AB6 -> 0 | J14: ='KH hieu chinh'!D14 -> 0 | K14: ='Thuc te theo thang'!AB208 -> 0 | L14: =C14+F14+I14 -> 900000000 | M14: =D14+G14+J14 -> 0 | N14: =E14+H14+K14 -> 0
A15: 11 | B15: Tháng 11 | C15: 900000000 | D15: ='KH hieu chinh'!M15 -> 0 | E15: ='Thuc te theo thang'!AD5 -> 0 | G15: ='KH hieu chinh'!C15 -> 0 | H15: ='Thuc te theo thang'!AD6 -> 0 | J15: ='KH hieu chinh'!D15 -> 0 | K15: ='Thuc te theo thang'!AD208 -> 0 | L15: =C15+F15+I15 -> 900000000 | M15: =D15+G15+J15 -> 0 | N15: =E15+H15+K15 -> 0
A16: 12 | B16: Tháng 12 | C16: 900000000 | D16: ='KH hieu chinh'!M16 -> 0 | E16: ='Thuc te theo thang'!AF5 -> 0 | G16: ='KH hieu chinh'!C16 -> 0 | H16: ='Thuc te theo thang'!AF6 -> 0 | J16: ='KH hieu chinh'!D16 -> 854990000 | K16: ='Thuc te theo thang'!AF208 -> 0 | L16: =C16+F16+I16 -> 900000000 | M16: =D16+G16+J16 -> 854990000 | N16: =E16+H16+K16 -> 0 | P16: =SUM(N14:N16) -> 0
B17: Năm | C17: =SUM(C5:C16) -> 10800000000 | D17: =SUM(D5:D16) -> 0 | E17: =SUM(E5:E16) -> 0 | F17: =SUM(F5:F16) -> 0 | G17: =SUM(G5:G16) -> 0 | H17: =SUM(H5:H16) -> 0 | I17: =SUM(I5:I16) -> 0 | J17: =SUM(J5:J16) -> 854990000 | K17: =SUM(K5:K16) -> 0 | L17: =C17+F17+I17 -> 10800000000 | M17: =D17+G17+J17 -> 854990000 | N17: =E17+H17+K17 -> 0
B18: Tỷ lệ | E18: =E17/C17 -> 0 | H18: =H17/F17 -> #DIV/0! | K18: =K17/I17 -> #DIV/0! | N18: =N17/L17 -> 0
M19: G2B+UNI | N19: =H17+K17 -> 0
C20: =SUM(C11:C13) -> 2700000000 | D20: =SUM(D11:D13) -> 0 | E20: =SUM(E11:E13) -> 0 | F20: =SUM(F11:F13) -> 0 | G20: =SUM(G11:G13) -> 0 | H20: =SUM(H11:H13) -> 0 | I20: =SUM(I11:I13) -> 0 | J20: =SUM(J11:J13) -> 0 | ... N20: =SUM(N11:N13) -> 0 | O20: =M20+N17 -> 0
D21: =D20/C20 -> 0 | G21: =G20/F20 -> #DIV/0! | J21: =J20/I20 -> #DIV/0! | M21: =M20/L20 -> 0 | O21: =O20/L17 -> 0
A22: DỰ KIẾN KẾT QUẢ ĐẠT ĐƯỢC SO VỚI KẾ HOẠCH NĂM
D23: ITO | G23: UNI | J23: G2B | M23: BPPM
A24: PP1: Tính theo mức độ | D24: Giá trị | E24: Tỷ lệ | G24: Giá trị | H24: Tỷ lệ | J24: Giá trị | K24: Tỷ lệ | M24: Giá trị | N24: Tỷ lệ
A25: Thực tế + Mức 1 | D25: =E17+D17 -> 0 | E25: =D25/C17 -> 0 | G25: =H17+'KH hieu chinh'!E17 -> 0 | H25: =G25/$F$17 -> #DIV/0! | J25: =(K17+'KH hieu chinh'!H17) -> 854990000 | K25: =J25/$I$17 -> #DIV/0! | M25: =D25+G25+J25 -> 854990000 | N25: =M25/$L$17 -> 0.079165741
A26: Thực tế + Mức 1+2 | G26: =G25+'KH hieu chinh'!F17 -> 0 | H26: =G26/$F$17 -> #DIV/0! | J26: =J25+'KH hieu chinh'!I17 -> 854990000 | K26: =J26/$I$17 -> #DIV/0! | M26: =D25+G26+J26 -> 854990000 | N26: =M26/$L$17 -> 0.079165741
A27: Thực tế + Mức 1+2+3 | G27: =G26+'KH hieu chinh'!G17 -> 0 | H27: =G27/$F$17 -> #DIV/0! | J27: =J26+'KH hieu chinh'!J17 -> 854990000 | K27: =J27/$I$17 -> #DIV/0! | M27: =D25+G27+J27 -> 854990000 | N27: =M27/$L$17 -> 0.079165741
A29: PP2: Tính theo thời gian | D29: Giá trị | E29: Tỷ lệ | G29: Giá trị | H29: Tỷ lệ | J29: Giá trị | K29: Tỷ lệ | M29: Giá trị | N29: Tỷ lệ
A30: Thực tế + Đến hết Quý III | D30: =E17+D17 -> 0 | E30: =D30/C17 -> 0 | G30: =H17+SUM('KH hieu chinh'!C11:C13) -> 0 | H30: =G30/$F$17 -> #DIV/0! | J30: =K17+SUM('KH hieu chinh'!D11:D13) -> 0 | K30: =J30/$I$17 -> #DIV/0! | M30: =D30+G30+J30 -> 0 | N30: =M30/$L$17 -> 0
A31: Thực tế + Đến hết Quý VI | G31: =G30+SUM('KH hieu chinh'!C14:C16) -> 0 | H31: =G31/$F$17 -> #DIV/0! | J31: =J30+SUM('KH hieu chinh'!D14:D16) -> 854990000 | K31: =J31/$I$17 -> #DIV/0! | M31: =D30+G31+J31 -> 854990000 | N31: =M31/$L$17 -> 0.079165741
K32: Kỳ hợp trước: | M32: 25877043393 | N32: 0.868
K33: Tăng/Giảm: | M33: =M31-M32 -> -25022053393 | N33: =N31-N32 -> -0.78883426
A34: DOANH THU
A35: STT | B35: Tháng | C35: Nhóm ITO | F35: Nhóm UNI | I35: Nhóm G2B | L35: BPPM
C36: KH đầu năm | D36: KH hiệu chỉnh | E36: Thực tế | F36: KH đầu năm | G36: KH hiệu chỉnh | H36: Thực tế | I36: KH đầu năm | J36: KH hiệu chỉnh | K36: Thực tế | L36: KH đầu năm | M36: KH hiệu chỉnh | N36: Thực tế
A37: 1 | B37: Tháng 01 | C37: 900000000 | D37: ='KH hieu chinh'!N5 -> 0 | E37: ='Thuc te theo thang'!K5 -> 0 | F37: 198000000 | G37: ='KH hieu chinh'!M30 -> 0 | H37: ='Thuc te theo thang'!K6 -> 0 | I37: 31786170 | J37: ='KH hieu chinh'!N30 -> 0 | K37: ='Thuc te theo thang'!K208 -> 0 | L37: =C37+F37+I37 -> 1129786170 | M37: =D37+G37+J37 -> 0 | N37: =E37+H37+K37 -> 0
A38: 2 | B38: Tháng 02 | C38: 900000000 | D38: ='KH hieu chinh'!N6 -> 0 | E38: ='Thuc te theo thang'!M5 -> 0 | F38: 0 | G38: ='KH hieu chinh'!M31 -> 0 | H38: ='Thuc te theo thang'!M6 -> 0 | I38: 0 | J38: ='KH hieu chinh'!N31 -> 0 | K38: ='Thuc te theo thang'!M208 -> 0 | L38: =C38+F38+I38 -> 900000000 | M38: =D38+G38+J38 -> 0 | N38: =E38+H38+K38 -> 0
A39: 3 | B39: Tháng 03 | C39: 900000000 | D39: ='KH hieu chinh'!N7 -> 0 | E39: ='Thuc te theo thang'!O5 -> 0 | F39: 624572500 | G39: ='KH hieu chinh'!M32 -> 0 | H39: ='Thuc te theo thang'!O6 -> 0 | I39: 16500000 | J39: ='KH hieu chinh'!N32 -> 0 | K39: ='Thuc te theo thang'!O208 -> 0 | L39: =C39+F39+I39 -> 1541072500 | M39: =D39+G39+J39 -> 0 | N39: =E39+H39+K39 -> 0 | P39: =SUM(O37:O39) -> 0
A40: 4 | B40: Tháng 04 | C40: 900000000 | D40: ='KH hieu chinh'!N8 -> 0 | E40: ='Thuc te theo thang'!Q5 -> 0 | F40: 198507000 | G40: ='KH hieu chinh'!M33 -> 0 | H40: ='Thuc te theo thang'!Q6 -> 0 | I40: 72000000 | J40: ='KH hieu chinh'!N33 -> 0 | K40: ='Thuc te theo thang'!Q208 -> 0 | L40: =C40+F40+I40 -> 1170507000 | M40: =D40+G40+J40 -> 0 | N40: =E40+H40+K40 -> 0
A41: 5 | B41: Tháng 05 | C41: 900000000 | D41: ='KH hieu chinh'!N9 -> 0 | E41: ='Thuc te theo thang'!S5 -> 0 | F41: 406300000 | G41: ='KH hieu chinh'!M34 -> 0 | H41: ='Thuc te theo thang'!S6 -> 0 | I41: 116250000 | J41: ='KH hieu chinh'!N34 -> 0 | K41: ='Thuc te theo thang'!S208 -> 0 | L41: =C41+F41+I41 -> 1422550000 | M41: =D41+G41+J41 -> 0 | N41: =E41+H41+K41 -> 0
...

Sheet TH_2026
A1: TỔNG HỢP THEO THÁNG
A2: HỢP ĐỒNG | C2: 2026
A3: STT | B3: Tháng | C3: Nhóm ITO | F3: Nhóm UNI | I3: Nhóm G2B | L3: BPPM
C4: KH đầu năm | D4: Cơ hội | E4: Thực tế | F4: KH đầu năm | G4: Cơ hội | H4: Thực tế | I4: KH đầu năm | J4: Cơ hội | K4: Thực tế | L4: KH đầu năm | M4: Cơ hội | N4: Thực tế
A5: 1 | B5: Tháng 01 | C5: =KH_Nam_Hieuchinh!C5 -> 950000000 | D5: =KH_Nam_Hieuchinh!G5 -> 0 | E5: =SUMPRODUCT( (HD_Thucte!$E$2:$E$1003)* (HD_Thucte!$A$2:$A$1003="ITO")* (YEAR(HD_Thucte!$F$2:$F$1003)=$C$2)* (MONTH(HD_Thucte!$F$2:$F$1003)=VALUE(RIGHT($B5,2))) ) -> 1003909178 | F5: =KH_Nam_Hieuchinh!D5 -> 42200000 | G5: =KH_Nam_Hieuchinh!H5 -> 0 | H5: =SUMPRODUCT( (HD_Thucte!$E$2:$E$1003)* (HD_Thucte!$A$2:$A$1003="UNI")* (YEAR(HD_Thucte!$F$2:$F$1003)=$C$2)* (MONTH(HD_Thucte!$F$2:$F$1003)=VALUE(RIGHT($B5,2))) ) -> 271200000 | I5: =KH_Nam_Hieuchinh!E5 -> 66000000 | J5: =KH_Nam_Hieuchinh!I5 -> 0 | K5: =SUMPRODUCT( (HD_Thucte!$E$2:$E$1003)* (HD_Thucte!$A$2:$A$1003="G2B")* (YEAR(HD_Thucte!$F$2:$F$1003)=$C$2)* (MONTH(HD_Thucte!$F$2:$F$1003)=VALUE(RIGHT($B5,2))) ) -> 34000000 | L5: =C5+F5+I5 -> 1058200000 | M5: =D5+G5+J5 -> 0 | N5: =E5+H5+K5 -> 1309109178
A6: 2 | B6: Tháng 02 | C6: =KH_Nam_Hieuchinh!C6 -> 950000000 | D6: =KH_Nam_Hieuchinh!G6 -> 0 | E6: =SUMPRODUCT( (HD_Thucte!$E$2:$E$1003)* (HD_Thucte!$A$2:$A$1003="ITO")* (YEAR(HD_Thucte!$F$2:$F$1003)=$C$2)* (MONTH(HD_Thucte!$F$2:$F$1003)=VALUE(RIGHT($B6,2))) ) -> 1022803457 | F6: =KH_Nam_Hieuchinh!D6 -> 200000000 | G6: =KH_Nam_Hieuchinh!H6 -> 0 | H6: =SUMPRODUCT( (HD_Thucte!$E$2:$E$1003)* (HD_Thucte!$A$2:$A$1003="UNI")* (YEAR(HD_Thucte!$F$2:$F$1003)=$C$2)* (MONTH(HD_Thucte!$F$2:$F$1003)=VALUE(RIGHT($B6,2))) ) -> 0 | I6: =KH_Nam_Hieuchinh!E6 -> 1500000000 | J6: =KH_Nam_Hieuchinh!I6 -> 0 | K6: =SUMPRODUCT( (HD_Thucte!$E$2:$E$1003)* (HD_Thucte!$A$2:$A$1003="G2B")* (YEAR(HD_Thucte!$F$2:$F$1003)=$C$2)* (MONTH(HD_Thucte!$F$2:$F$1003)=VALUE(RIGHT($B6,2))) ) -> 1749791000 | L6: =C6+F6+I6 -> 2650000000 | M6: =D6+G6+J6 -> 0 | N6: =E6+H6+K6 -> 2772594457
A7: 3 | B7: Tháng 03 | C7: =KH_Nam_Hieuchinh!C7 -> 950000000 | D7: =KH_Nam_Hieuchinh!G7 -> 0 | E7: =SUMPRODUCT( (HD_Thucte!$E$2:$E$1003)* (HD_Thucte!$A$2:$A$1003="ITO")* (YEAR(HD_Thucte!$F$2:$F$1003)=$C$2)* (MONTH(HD_Thucte!$F$2:$F$1003)=VALUE(RIGHT($B7,2))) ) -> 960679500 | F7: =KH_Nam_Hieuchinh!D7 -> 1000000000 | G7: =KH_Nam_Hieuchinh!H7 -> 0 | H7: =SUMPRODUCT( (HD_Thucte!$E$2:$E$1003)* (HD_Thucte!$A$2:$A$1003="UNI")* (YEAR(HD_Thucte!$F$2:$F$1003)=$C$2)* (MONTH(HD_Thucte!$F$2:$F$1003)=VALUE(RIGHT($B7,2))) ) -> 39540000 | I7: =KH_Nam_Hieuchinh!E7 -> 500000000 | J7: =KH_Nam_Hieuchinh!I7 -> 0 | K7: =SUMPRODUCT( (HD_Thucte!$E$2:$E$1003)* (HD_Thucte!$A$2:$A$1003="G2B")* (YEAR(HD_Thucte!$F$2:$F$1003)=$C$2)* (MONTH(HD_Thucte!$F$2:$F$1003)=VALUE(RIGHT($B7,2))) ) -> 60000000 | L7: =C7+F7+I7 -> 2450000000 | M7: =D7+G7+J7 -> 0 | N7: =E7+H7+K7 -> 1060219500 | O7: =SUM(N5:N7) -> 5141923135
A8: 4 | B8: Tháng 04 | C8: =KH_Nam_Hieuchinh!C8 -> 950000000 | D8: =KH_Nam_Hieuchinh!G8 -> 0 | E8: =SUMPRODUCT( (HD_Thucte!$E$2:$E$1003)* (HD_Thucte!$A$2:$A$1003="ITO")* (YEAR(HD_Thucte!$F$2:$F$1003)=$C$2)* (MONTH(HD_Thucte!$F$2:$F$1003)=VALUE(RIGHT($B8,2))) ) -> 963300542 | F8: =KH_Nam_Hieuchinh!D8 -> 800800000 | G8: =KH_Nam_Hieuchinh!H8 -> 0 | H8: =SUMPRODUCT( (HD_Thucte!$E$2:$E$1003)* (HD_Thucte!$A$2:$A$1003="UNI")* (YEAR(HD_Thucte!$F$2:$F$1003)=$C$2)* (MONTH(HD_Thucte!$F$2:$F$1003)=VALUE(RIGHT($B8,2))) ) -> 3017125000 | I8: =KH_Nam_Hieuchinh!E8 -> 1000000000 | J8: =KH_Nam_Hieuchinh!I8 -> 0 | K8: =SUMPRODUCT( (HD_Thucte!$E$2:$E$1003)* (HD_Thucte!$A$2:$A$1003="G2B")* (YEAR(HD_Thucte!$F$2:$F$1003)=$C$2)* (MONTH(HD_Thucte!$F$2:$F$1003)=VALUE(RIGHT($B8,2))) ) -> 67000000 | L8: =C8+F8+I8 -> 2750800000 | M8: =D8+G8+J8 -> 0 | N8: =E8+H8+K8 -> 4047425542
A9: 5 | B9: Tháng 05 | C9: =KH_Nam_Hieuchinh!C9 -> 950000000 | D9: =KH_Nam_Hieuchinh!G9 -> 0 | E9: =SUMPRODUCT( (HD_Thucte!$E$2:$E$1003)* (HD_Thucte!$A$2:$A$1003="ITO")* (YEAR(HD_Thucte!$F$2:$F$1003)=$C$2)* (MONTH(HD_Thucte!$F$2:$F$1003)=VALUE(RIGHT($B9,2))) ) -> 924438273 | F9: =KH_Nam_Hieuchinh!D9 -> 1357000000 | G9: =KH_Nam_Hieuchinh!H9 -> 0 | H9: =SUMPRODUCT( (HD_Thucte!$E$2:$E$1003)* (HD_Thucte!$A$2:$A$1003="UNI")* (YEAR(HD_Thucte!$F$2:$F$1003)=$C$2)* (MONTH(HD_Thucte!$F$2:$F$1003)=VALUE(RIGHT($B9,2))) ) -> 13200000 | I9: =KH_Nam_Hieuchinh!E9 -> 600000000 | J9: =KH_Nam_Hieuchinh!I9 -> 0 | K9: =SUMPRODUCT( (HD_Thucte!$E$2:$E$1003)* (HD_Thucte!$A$2:$A$1003="G2B")* (YEAR(HD_Thucte!$F$2:$F$1003)=$C$2)* (MONTH(HD_Thucte!$F$2:$F$1003)=VALUE(RIGHT($B9,2))) ) -> 40000000 | L9: =C9+F9+I9 -> 2907000000 | M9: =D9+G9+J9 -> 0 | N9: =E9+H9+K9 -> 977638273
A10: 6 | B10: Tháng 06 | C10: =KH_Nam_Hieuchinh!C10 -> 950000000 | D10: =KH_Nam_Hieuchinh!G10 -> 0 | E10: =SUMPRODUCT( (HD_Thucte!$E$2:$E$1003)* (HD_Thucte!$A$2:$A$1003="ITO")* (YEAR(HD_Thucte!$F$2:$F$1003)=$C$2)* (MONTH(HD_Thucte!$F$2:$F$1003)=VALUE(RIGHT($B10,2))) ) -> 858195940 | F10: =KH_Nam_Hieuchinh!D10 -> 1200000000 | G10: =KH_Nam_Hieuchinh!H10 -> 0 | H10: =SUMPRODUCT( (HD_Thucte!$E$2:$E$1003)* (HD_Thucte!$A$2:$A$1003="UNI")* (YEAR(HD_Thucte!$F$2:$F$1003)=$C$2)* (MONTH(HD_Thucte!$F$2:$F$1003)=VALUE(RIGHT($B10,2))) ) -> 106500000 | I10: =KH_Nam_Hieuchinh!E10 -> 500000000 | J10: =KH_Nam_Hieuchinh!I10 -> 0 | K10: =SUMPRODUCT( (HD_Thucte!$E$2:$E$1003)* (HD_Thucte!$A$2:$A$1003="G2B")* (YEAR(HD_Thucte!$F$2:$F$1003)=$C$2)* (MONTH(HD_Thucte!$F$2:$F$1003)=VALUE(RIGHT($B10,2))) ) -> 123500000 | L10: =C10+F10+I10 -> 2650000000 | M10: =D10+G10+J10 -> 0 | N10: =E10+H10+K10 -> 1088195940 | O10: =SUM(N8:N10) -> 6113259755
A11: 7 | B11: Tháng 07 | C11: =KH_Nam_Hieuchinh!C11 -> 950000000 | D11: =KH_Nam_Hieuchinh!G11 -> 0 | E11: =SUMPRODUCT( (HD_Thucte!$E$2:$E$1003)* (HD_Thucte!$A$2:$A$1003="ITO")* (YEAR(HD_Thucte!$F$2:$F$1003)=$C$2)* (MONTH(HD_Thucte!$F$2:$F$1003)=VALUE(RIGHT($B11,2))) ) -> 867129105 | F11: =KH_Nam_Hieuchinh!D11 -> 900000000 | G11: =KH_Nam_Hieuchinh!H11 -> 0 | H11: =SUMPRODUCT( (HD_Thucte!$E$2:$E$1003)* (HD_Thucte!$A$2:$A$1003="UNI")* (YEAR(HD_Thucte!$F$2:$F$1003)=$C$2)* (MONTH(HD_Thucte!$F$2:$F$1003)=VALUE(RIGHT($B11,2))) ) -> 0 | I11: =KH_Nam_Hieuchinh!E11 -> 500000000 | J11: =KH_Nam_Hieuchinh!I11 -> 0 | K11: =SUMPRODUCT( (HD_Thucte!$E$2:$E$1003)* (HD_Thucte!$A$2:$A$1003="G2B")* (YEAR(HD_Thucte!$F$2:$F$1003)=$C$2)* (MONTH(HD_Thucte!$F$2:$F$1003)=VALUE(RIGHT($B11,2))) ) -> 16500000 | L11: =C11+F11+I11 -> 2350000000 | M11: =D11+G11+J11 -> 0 | N11: =E11+H11+K11 -> 883629105
A12: 8 | B12: Tháng 08 | C12: =KH_Nam_Hieuchinh!C12 -> 950000000 | D12: =KH_Nam_Hieuchinh!G12 -> 0 | E12: =SUMPRODUCT( (HD_Thucte!$E$2:$E$1003)* (HD_Thucte!$A$2:$A$1003="ITO")* (YEAR(HD_Thucte!$F$2:$F$1003)=$C$2)* (MONTH(HD_Thucte!$F$2:$F$1003)=VALUE(RIGHT($B12,2))) ) -> 866631085 | F12: =KH_Nam_Hieuchinh!D12 -> 800000000 | G12: =KH_Nam_Hieuchinh!H12 -> 0 | H12: =SUMPRODUCT( (HD_Thucte!$E$2:$E$1003)* (HD_Thucte!$A$2:$A$1003="UNI")* (YEAR(HD_Thucte!$F$2:$F$1003)=$C$2)* (MONTH(HD_Thucte!$F$2:$F$1003)=VALUE(RIGHT($B12,2))) ) -> 134205000 | I12: =KH_Nam_Hieuchinh!E12 -> 1300000000 | J12: =KH_Nam_Hieuchinh!I12 -> 0 | K12: =SUMPRODUCT( (HD_Thucte!$E$2:$E$1003)* (HD_Thucte!$A$2:$A$1003="G2B")* (YEAR(HD_Thucte!$F$2:$F$1003)=$C$2)* (MONTH(HD_Thucte!$F$2:$F$1003)=VALUE(RIGHT($B12,2))) ) -> 0 | L12: =C12+F12+I12 -> 3050000000 | M12: =D12+G12+J12 -> 0 | N12: =E12+H12+K12 -> 1000836085
A13: 9 | B13: Tháng 09 | C13: =KH_Nam_Hieuchinh!C13 -> 950000000 | D13: =KH_Nam_Hieuchinh!G13 -> 950000000 | E13: =SUMPRODUCT( (HD_Thucte!$E$2:$E$1003)* (HD_Thucte!$A$2:$A$1003="ITO")* (YEAR(HD_Thucte!$F$2:$F$1003)=$C$2)* (MONTH(HD_Thucte!$F$2:$F$1003)=VALUE(RIGHT($B13,2))) ) -> 0 | F13: =KH_Nam_Hieuchinh!D13 -> 1100000000 | G13: =KH_Nam_Hieuchinh!H13 -> 7724770000 | H13: =SUMPRODUCT( (HD_Thucte!$E$2:$E$1003)* (HD_Thucte!$A$2:$A$1003="UNI")* (YEAR(HD_Thucte!$F$2:$F$1003)=$C$2)* (MONTH(HD_Thucte!$F$2:$F$1003)=VALUE(RIGHT($B13,2))) ) -> 27500000 | I13: =KH_Nam_Hieuchinh!E13 -> 1334000000 | J13: =KH_Nam_Hieuchinh!I13 -> 3635980000 | K13: =SUMPRODUCT( (HD_Thucte!$E$2:$E$1003)* (HD_Thucte!$A$2:$A$1003="G2B")* (YEAR(HD_Thucte!$F$2:$F$1003)=$C$2)* (MONTH(HD_Thucte!$F$2:$F$1003)=VALUE(RIGHT($B13,2))) ) -> 510000000 | L13: =C13+F13+I13 -> 3384000000 | M13: =D13+G13+J13 -> 12310750000 | N13: =E13+H13+K13 -> 537500000 | O13: =SUM(N11:N13) -> 2421965190
A14: 10 | B14: Tháng 10 | C14: =KH_Nam_Hieuchinh!C14 -> 950000000 | D14: =KH_Nam_Hieuchinh!G14 -> 950000000 | E14: =SUMPRODUCT( (HD_Thucte!$E$2:$E$1003)* (HD_Thucte!$A$2:$A$1003="ITO")* (YEAR(HD_Thucte!$F$2:$F$1003)=$C$2)* (MONTH(HD_Thucte!$F$2:$F$1003)=VALUE(RIGHT($B14,2))) ) -> 0 | F14: =KH_Nam_Hieuchinh!D14 -> 800000000 | G14: =KH_Nam_Hieuchinh!H14 -> 7444236000 | H14: =SUMPRODUCT( (HD_Thucte!$E$2:$E$1003)* (HD_Thucte!$A$2:$A$1003="UNI")* (YEAR(HD_Thucte!$F$2:$F$1003)=$C$2)* (MONTH(HD_Thucte!$F$2:$F$1003)=VALUE(RIGHT($B14,2))) ) -> 13500000 | I14: =KH_Nam_Hieuchinh!E14 -> 800000000 | J14: =KH_Nam_Hieuchinh!I14 -> 328250000 | K14: =SUMPRODUCT( (HD_Thucte!$E$2:$E$1003)* (HD_Thucte!$A$2:$A$1003="G2B")* (YEAR(HD_Thucte!$F$2:$F$1003)=$C$2)* (MONTH(HD_Thucte!$F$2:$F$1003)=VALUE(RIGHT($B14,2))) ) -> 0 | L14: =C14+F14+I14 -> 2550000000 | M14: =D14+G14+J14 -> 8722486000 | N14: =E14+H14+K14 -> 13500000
A15: 11 | B15: Tháng 11 | C15: =KH_Nam_Hieuchinh!C15 -> 950000000 | D15: =KH_Nam_Hieuchinh!G15 -> 950000000 | E15: =SUMPRODUCT( (HD_Thucte!$E$2:$E$1003)* (HD_Thucte!$A$2:$A$1003="ITO")* (YEAR(HD_Thucte!$F$2:$F$1003)=$C$2)* (MONTH(HD_Thucte!$F$2:$F$1003)=VALUE(RIGHT($B15,2))) ) -> 0 | F15: =KH_Nam_Hieuchinh!D15 -> 900000000 | G15: =KH_Nam_Hieuchinh!H15 -> 102825000 | H15: =SUMPRODUCT( (HD_Thucte!$E$2:$E$1003)* (HD_Thucte!$A$2:$A$1003="UNI")* (YEAR(HD_Thucte!$F$2:$F$1003)=$C$2)* (MONTH(HD_Thucte!$F$2:$F$1003)=VALUE(RIGHT($B15,2))) ) -> 0 | I15: =KH_Nam_Hieuchinh!E15 -> 900000000 | J15: =KH_Nam_Hieuchinh!I15 -> 3003500000 | K15: =SUMPRODUCT( (HD_Thucte!$E$2:$E$1003)* (HD_Thucte!$A$2:$A$1003="G2B")* (YEAR(HD_Thucte!$F$2:$F$1003)=$C$2)* (MONTH(HD_Thucte!$F$2:$F$1003)=VALUE(RIGHT($B15,2))) ) -> 0 | L15: =C15+F15+I15 -> 2750000000 | M15: =D15+G15+J15 -> 4056325000 | N15: =E15+H15+K15 -> 0
A16: 12 | B16: Tháng 12 | C16: =KH_Nam_Hieuchinh!C16 -> 950000000 | D16: =KH_Nam_Hieuchinh!G16 -> 950000000 | E16: =SUMPRODUCT( (HD_Thucte!$E$2:$E$1003)* (HD_Thucte!$A$2:$A$1003="ITO")* (YEAR(HD_Thucte!$F$2:$F$1003)=$C$2)* (MONTH(HD_Thucte!$F$2:$F$1003)=VALUE(RIGHT($B16,2))) ) -> 0 | F16: =KH_Nam_Hieuchinh!D16 -> 1000000000 | G16: =KH_Nam_Hieuchinh!H16 -> 734300000 | H16: =SUMPRODUCT( (HD_Thucte!$E$2:$E$1003)* (HD_Thucte!$A$2:$A$1003="UNI")* (YEAR(HD_Thucte!$F$2:$F$1003)=$C$2)* (MONTH(HD_Thucte!$F$2:$F$1003)=VALUE(RIGHT($B16,2))) ) -> 0 | I16: =KH_Nam_Hieuchinh!E16 -> 1000000000 | J16: =KH_Nam_Hieuchinh!I16 -> 3108712000 | K16: =SUMPRODUCT( (HD_Thucte!$E$2:$E$1003)* (HD_Thucte!$A$2:$A$1003="G2B")* (YEAR(HD_Thucte!$F$2:$F$1003)=$C$2)* (MONTH(HD_Thucte!$F$2:$F$1003)=VALUE(RIGHT($B16,2))) ) -> 0 | L16: =C16+F16+I16 -> 2950000000 | M16: =D16+G16+J16 -> 4793012000 | N16: =E16+H16+K16 -> 0 | O16: =SUM(N14:N16) -> 13500000
B17: Năm | C17: =SUM(C5:C16) -> 11400000000 | D17: =SUM(D5:D16) -> 3800000000 | E17: =SUM(E5:E16) -> 7467087080 | F17: =SUM(F5:F16) -> 10100000000 | G17: =SUM(G5:G16) -> 16006131000 | H17: =SUM(H5:H16) -> 3622770000 | I17: =SUM(I5:I16) -> 10000000000 | J17: =SUM(J5:J16) -> 10076442000 | K17: =SUM(K5:K16) -> 2600791000 | L17: =C17+F17+I17 -> 31500000000 | M17: =D17+G17+J17 -> 29882573000 | N17: =E17+H17+K17 -> 13690648080
B18: Tỷ lệ | E18: =E17/C17 -> 0.65500764 | H18: =H17/F17 -> 0.3586901 | K18: =K17/I17 -> 0.2600791 | N18: =N17/L17 -> 0.43462375
M19: G2B+UNI | N19: =H17+K17 -> 6223561000
A20: DOANH THU | C20: 2026
A21: STT | B21: Tháng | C21: Nhóm ITO | F21: Nhóm UNI | J21: Nhóm G2B | N21: BPPM
C22: KH đầu năm | D22: Cơ hội | E22: Thực tế | F22: KH đầu năm | G22: Đang thực hiện | H22: Cơ hội | I22: Thực tế | J22: KH đầu năm | K22: Đang thực hiện | L22: Cơ hội | M22: Thực tế | N22: KH đầu năm | O22: Đang thực hiện | P22: Cơ hội | Q22: Thực tế
A23: 1 | B23: Tháng 01 | C23: =KH_Nam_Hieuchinh!C22 -> 950000000 | D23: =KH_Nam_Hieuchinh!G22 -> 0 | E23: =SUMPRODUCT( (DT_Thucte!$E$2:$E$1007)* (DT_Thucte!$A$2:$A$1007="ITO")* (YEAR(DT_Thucte!$F$2:$F$1007)=$C$20)* (MONTH(DT_Thucte!$F$2:$F$1007)=VALUE(RIGHT($B23,2))) ) -> 1003909178 | F23: =KH_Nam_Hieuchinh!D22 -> 851000000 | G23: =SUMPRODUCT( ('KH DT_HD da ky'!$E$2:$E$993)* ('KH DT_HD da ky'!$A$2:$A$993="UNI")* (YEAR('KH DT_HD da ky'!$F$2:$F$993)=$C$20)* (MONTH('KH DT_HD da ky'!$F$2:$F$993)=VALUE(RIGHT($B23,2))) ) -> 0 | H23: =KH_Nam_Hieuchinh!H22 -> 0 | I23: =SUMPRODUCT( (DT_Thucte!$E$2:$E$1007)* (DT_Thucte!$A$2:$A$1007="UNI")* (YEAR(DT_Thucte!$F$2:$F$1007)=$C$20)* (MONTH(DT_Thucte!$F$2:$F$1007)=VALUE(RIGHT($B23,2))) ) -> 472766000 | J23: =KH_Nam_Hieuchinh!E22 -> 270000000 | K23: =SUMPRODUCT( ('KH DT_HD da ky'!$E$2:$E$993)* ('KH DT_HD da ky'!$A$2:$A$993="G2B")* (YEAR('KH DT_HD da ky'!$F$2:$F$993)=$C$20)* (MONTH('KH DT_HD da ky'!$F$2:$F$993)=VALUE(RIGHT($B23,2))) ) -> 0 | L23: =KH_Nam_Hieuchinh!I22 -> 0 | M23: =SUMPRODUCT( (DT_Thucte!$E$2:$E$1007)* (DT_Thucte!$A$2:$A$1007="G2B")* (YEAR(DT_Thucte!$F$2:$F$1007)=$C$20)* (MONTH(DT_Thucte!$F$2:$F$1007)=VALUE(RIGHT($B23,2))) ) -> 96000000 | N23: =C23+F23+J23 -> 2071000000 | O23: =G23+K23 -> 0 | P23: =D23+H23+L23 -> 0 | Q23: =E23+I23+M23 -> 1572675178
A24: 2 | B24: Tháng 02 | C24: =KH_Nam_Hieuchinh!C23 -> 950000000 | D24: =KH_Nam_Hieuchinh!G23 -> 0 | E24: =SUMPRODUCT( (DT_Thucte!$E$2:$E$1007)* (DT_Thucte!$A$2:$A$1007="ITO")* (YEAR(DT_Thucte!$F$2:$F$1007)=$C$20)* (MONTH(DT_Thucte!$F$2:$F$1007)=VALUE(RIGHT($B24,2))) ) -> 1022803457 | F24: =KH_Nam_Hieuchinh!D23 -> 30000000 | G24: =SUMPRODUCT( ('KH DT_HD da ky'!$E$2:$E$993)* ('KH DT_HD da ky'!$A$2:$A$993="UNI")* (YEAR('KH DT_HD da ky'!$F$2:$F$993)=$C$20)* (MONTH('KH DT_HD da ky'!$F$2:$F$993)=VALUE(RIGHT($B24,2))) ) -> 0 | H24: =KH_Nam_Hieuchinh!H23 -> 0 | I24: =SUMPRODUCT( (DT_Thucte!$E$2:$E$1007)* (DT_Thucte!$A$2:$A$1007="UNI")* (YEAR(DT_Thucte!$F$2:$F$1007)=$C$20)* (MONTH(DT_Thucte!$F$2:$F$1007)=VALUE(RIGHT($B24,2))) ) -> 507326000 | J24: =KH_Nam_Hieuchinh!E23 -> 1405000000 | K24: =SUMPRODUCT( ('KH DT_HD da ky'!$E$2:$E$993)* ('KH DT_HD da ky'!$A$2:$A$993="G2B")* (YEAR('KH DT_HD da ky'!$F$2:$F$993)=$C$20)* (MONTH('KH DT_HD da ky'!$F$2:$F$993)=VALUE(RIGHT($B24,2))) ) -> 0 | L24: =KH_Nam_Hieuchinh!I23 -> 0 | M24: =SUMPRODUCT( (DT_Thucte!$E$2:$E$1007)* (DT_Thucte!$A$2:$A$1007="G2B")* (YEAR(DT_Thucte!$F$2:$F$1007)=$C$20)* (MONTH(DT_Thucte!$F$2:$F$1007)=VALUE(RIGHT($B24,2))) ) -> 0 | N24: =C24+F24+J24 -> 2385000000 | O24: =G24+K24 -> 0 | P24: =D24+H24+L24 -> 0 | Q24: =E24+I24+M24 -> 1530129457
A25: 3 | B25: Tháng 03 | C25: =KH_Nam_Hieuchinh!C24 -> 950000000 | D25: =KH_Nam_Hieuchinh!G24 -> 0 | E25: =SUMPRODUCT( (DT_Thucte!$E$2:$E$1007)* (DT_Thucte!$A$2:$A$1007="ITO")* (YEAR(DT_Thucte!$F$2:$F$1007)=$C$20)* (MONTH(DT_Thucte!$F$2:$F$1007)=VALUE(RIGHT($B25,2))) ) -> 960679500 | F25: =KH_Nam_Hieuchinh!D24 -> 770000000 | G25: =SUMPRODUCT( ('KH DT_HD da ky'!$E$2:$E$993)* ('KH DT_HD da ky'!$A$2:$A$993="UNI")* (YEAR('KH DT_HD da ky'!$F$2:$F$993)=$C$20)* (MONTH('KH DT_HD da ky'!$F$2:$F$993)=VALUE(RIGHT($B25,2))) ) -> 0 | H25: =KH_Nam_Hieuchinh!H24 -> 0 | I25: =SUMPRODUCT( (DT_Thucte!$E$2:$E$1007)* (DT_Thucte!$A$2:$A$1007="UNI")* (YEAR(DT_Thucte!$F$2:$F$1007)=$C$20)* (MONTH(DT_Thucte!$F$2:$F$1007)=VALUE(RIGHT($B25,2))) ) -> 65000000 | J25: =KH_Nam_Hieuchinh!E24 -> 500000000 | K25: =SUMPRODUCT( ('KH DT_HD da ky'!$E$2:$E$993)* ('KH DT_HD da ky'!$A$2:$A$993="G2B")* (YEAR('KH DT_HD da ky'!$F$2:$F$993)=$C$20)* (MONTH('KH DT_HD da ky'!$F$2:$F$993)=VALUE(RIGHT($B25,2))) ) -> 0 | L25: =KH_Nam_Hieuchinh!I24 -> 0 | M25: =SUMPRODUCT( (DT_Thucte!$E$2:$E$1007)* (DT_Thucte!$A$2:$A$1007="G2B")* (YEAR(DT_Thucte!$F$2:$F$1007)=$C$20)* (MONTH(DT_Thucte!$F$2:$F$1007)=VALUE(RIGHT($B25,2))) ) -> 166532400 | N25: =C25+F25+J25 -> 2220000000 | O25: =G25+K25 -> 0 | P25: =D25+H25+L25 -> 0 | Q25: =E25+I25+M25 -> 1192211900 | R25: =SUM(Q23:Q25) -> 4295016535
A26: 4 | B26: Tháng 04 | C26: =KH_Nam_Hieuchinh!C25 -> 950000000 | D26: =KH_Nam_Hieuchinh!G25 -> 0 | E26: =SUMPRODUCT( (DT_Thucte!$E$2:$E$1007)* (DT_Thucte!$A$2:$A$1007="ITO")* (YEAR(DT_Thucte!$F$2:$F$1007)=$C$20)* (MONTH(DT_Thucte!$F$2:$F$1007)=VALUE(RIGHT($B26,2))) ) -> 963300542 | F26: =KH_Nam_Hieuchinh!D25 -> 660000000 | G26: =SUMPRODUCT( ('KH DT_HD da ky'!$E$2:$E$993)* ('KH DT_HD da ky'!$A$2:$A$993="UNI")* (YEAR('KH DT_HD da ky'!$F$2:$F$993)=$C$20)* (MONTH('KH DT_HD da ky'!$F$2:$F$993)=VALUE(RIGHT($B26,2))) ) -> 0 | H26: =KH_Nam_Hieuchinh!H25 -> 0 | I26: =SUMPRODUCT( (DT_Thucte!$E$2:$E$1007)* (DT_Thucte!$A$2:$A$1007="UNI")* (YEAR(DT_Thucte!$F$2:$F$1007)=$C$20)* (MONTH(DT_Thucte!$F$2:$F$1007)=VALUE(RIGHT($B26,2))) ) -> 39540000 | J26: =KH_Nam_Hieuchinh!E25 -> 890000000 | K26: =SUMPRODUCT( ('KH DT_HD da ky'!$E$2:$E$993)* ('KH DT_HD da ky'!$A$2:$A$993="G2B")* (YEAR('KH DT_HD da ky'!$F$2:$F$993)=$C$20)* (MONTH('KH DT_HD da ky'!$F$2:$F$993)=VALUE(RIGHT($B26,2))) ) -> 0 | L26: =KH_Nam_Hieuchinh!I25 -> 0 | M26: =SUMPRODUCT( (DT_Thucte!$E$2:$E$1007)* (DT_Thucte!$A$2:$A$1007="G2B")* (YEAR(DT_Thucte!$F$2:$F$1007)=$C$20)* (MONTH(DT_Thucte!$F$2:$F$1007)=VALUE(RIGHT($B26,2))) ) -> 644690411 | N26: =C26+F26+J26 -> 2500000000 | O26: =G26+K26 -> 0 | P26: =D26+H26+L26 -> 0 | Q26: =E26+I26+M26 -> 1647530953
A27: 5 | B27: Tháng 05 | C27: =KH_Nam_Hieuchinh!C26 -> 950000000 | D27: =KH_Nam_Hieuchinh!G26 -> 0 | E27: =SUMPRODUCT( (DT_Thucte!$E$2:$E$1007)* (DT_Thucte!$A$2:$A$1007="ITO")* (YEAR(DT_Thucte!$F$2:$F$1007)=$C$20)* (MONTH(DT_Thucte!$F$2:$F$1007)=VALUE(RIGHT($B27,2))) ) -> 924438273 | F27: =KH_Nam_Hieuchinh!D26 -> 865000000 | G27: =SUMPRODUCT( ('KH DT_HD da ky'!$E$2:$E$993)* ('KH DT_HD da ky'!$A$2:$A$993="UNI")* (YEAR('KH DT_HD da ky'!$F$2:$F$993)=$C$20)* (MONTH('KH DT_HD da ky'!$F$2:$F$993)=VALUE(RIGHT($B27,2))) ) -> 0 | H27: =KH_Nam_Hieuchinh!H26 -> 0 | I27: =SUMPRODUCT( (DT_Thucte!$E$2:$E$1007)* (DT_Thucte!$A$2:$A$1007="UNI")* (YEAR(DT_Thucte!$F$2:$F$1007)=$C$20)* (MONTH(DT_Thucte!$F$2:$F$1007)=VALUE(RIGHT($B27,2))) ) -> 939757500 | J27: =KH_Nam_Hieuchinh!E26 -> 300000000 | K27: =SUMPRODUCT( ('KH DT_HD da ky'!$E$2:$E$993)* ('KH DT_HD da ky'!$A$2:$A$993="G2B")* (YEAR('KH DT_HD da ky'!$F$2:$F$993)=$C$20)* (MONTH('KH DT_HD da ky'!$F$2:$F$993)=VALUE(RIGHT($B27,2))) ) -> 0 | L27: =KH_Nam_Hieuchinh!I26 -> 0 | M27: =SUMPRODUCT( (DT_Thucte!$E$2:$E$1007)* (DT_Thucte!$A$2:$A$1007="G2B")* (YEAR(DT_Thucte!$F$2:$F$1007)=$C$20)* (MONTH(DT_Thucte!$F$2:$F$1007)=VALUE(RIGHT($B27,2))) ) -> 1068245500 | N27: =C27+F27+J27 -> 2115000000 | O27: =G27+K27 -> 0 | P27: =D27+H27+L27 -> 0 | Q27: =E27+I27+M27 -> 2932441273
A28: 6 | B28: Tháng 06 | C28: =KH_Nam_Hieuchinh!C27 -> 950000000 | D28: =KH_Nam_Hieuchinh!G27 -> 0 | E28: =SUMPRODUCT( (DT_Thucte!$E$2:$E$1007)* (DT_Thucte!$A$2:$A$1007="ITO")* (YEAR(DT_Thucte!$F$2:$F$1007)=$C$20)* (MONTH(DT_Thucte!$F$2:$F$1007)=VALUE(RIGHT($B28,2))) ) -> 858195940 | F28: =KH_Nam_Hieuchinh!D27 -> 870000000 | G28: =SUMPRODUCT( ('KH DT_HD da ky'!$E$2:$E$993)* ('KH DT_HD da ky'!$A$2:$A$993="UNI")* (YEAR('KH DT_HD da ky'!$F$2:$F$993)=$C$20)* (MONTH('KH DT_HD da ky'!$F$2:$F$993)=VALUE(RIGHT($B28,2))) ) -> 0 | H28: =KH_Nam_Hieuchinh!H27 -> 0 | I28: =SUMPRODUCT( (DT_Thucte!$E$2:$E$1007)* (DT_Thucte!$A$2:$A$1007="UNI")* (YEAR(DT_Thucte!$F$2:$F$1007)=$C$20)* (MONTH(DT_Thucte!$F$2:$F$1007)=VALUE(RIGHT($B28,2))) ) -> 559461600 | J28: =KH_Nam_Hieuchinh!E27 -> 765000000 | K28: =SUMPRODUCT( ('KH DT_HD da ky'!$E$2:$E$993)* ('KH DT_HD da ky'!$A$2:$A$993="G2B")* (YEAR('KH DT_HD da ky'!$F$2:$F$993)=$C$20)* (MONTH('KH DT_HD da ky'!$F$2:$F$993)=VALUE(RIGHT($B28,2))) ) -> 0 | L28: =KH_Nam_Hieuchinh!I27 -> 0 | M28: =SUMPRODUCT( (DT_Thucte!$E$2:$E$1007)* (DT_Thucte!$A$2:$A$1007="G2B")* (YEAR(DT_Thucte!$F$2:$F$1007)=$C$20)* (MONTH(DT_Thucte!$F$2:$F$1007)=VALUE(RIGHT($B28,2))) ) -> 588000000 | N28: =C28+F28+J28 -> 2585000000 | O28: =G28+K28 -> 0 | P28: =D28+H28+L28 -> 0 | Q28: =E28+I28+M28 -> 2005657540 | R28: =SUM(Q26:Q28) -> 6585629766
A29: 7 | B29: Tháng 07 | C29: =KH_Nam_Hieuchinh!C28 -> 950000000 | D29: =KH_Nam_Hieuchinh!G28 -> 0 | E29: =SUMPRODUCT( (DT_Thucte!$E$2:$E$1007)* (DT_Thucte!$A$2:$A$1007="ITO")* (YEAR(DT_Thucte!$F$2:$F$1007)=$C$20)* (MONTH(DT_Thucte!$F$2:$F$1007)=VALUE(RIGHT($B29,2))) ) -> 867129105 | F29: =KH_Nam_Hieuchinh!D28 -> 670000000 | G29: =SUMPRODUCT( ('KH DT_HD da ky'!$E$2:$E$993)* ('KH DT_HD da ky'!$A$2:$A$993="UNI")* (YEAR('KH DT_HD da ky'!$F$2:$F$993)=$C$20)* (MONTH('KH DT_HD da ky'!$F$2:$F$993)=VALUE(RIGHT($B29,2))) ) -> 0 | H29: =KH_Nam_Hieuchinh!H28 -> 0 | I29: =SUMPRODUCT( (DT_Thucte!$E$2:$E$1007)* (DT_Thucte!$A$2:$A$1007="UNI")* (YEAR(DT_Thucte!$F$2:$F$1007)=$C$20)* (MONTH(DT_Thucte!$F$2:$F$1007)=VALUE(RIGHT($B29,2))) ) -> 2197067500 | J29: =KH_Nam_Hieuchinh!E28 -> 400000000 | K29: =SUMPRODUCT( ('KH DT_HD da ky'!$E$2:$E$993)* ('KH DT_HD da ky'!$A$2:$A$993="G2B")* (YEAR('KH DT_HD da ky'!$F$2:$F$993)=$C$20)* (MONTH('KH DT_HD da ky'!$F$2:$F$993)=VALUE(RIGHT($B29,2))) ) -> 0 | L29: =KH_Nam_Hieuchinh!I28 -> 0 | M29: =SUMPRODUCT( (DT_Thucte!$E$2:$E$1007)* (DT_Thucte!$A$2:$A$1007="G2B")* (YEAR(DT_Thucte!$F$2:$F$1007)=$C$20)* (MONTH(DT_Thucte!$F$2:$F$1007)=VALUE(RIGHT($B29,2))) ) -> 16500000 | N29: =C29+F29+J29 -> 2020000000 | O29: =G29+K29 -> 0 | P29: =D29+H29+L29 -> 0 | Q29: =E29+I29+M29 -> 3080696605
A30: 8 | B30: Tháng 08 | C30: =KH_Nam_Hieuchinh!C29 -> 950000000 | D30: =KH_Nam_Hieuchinh!G29 -> 0 | E30: =SUMPRODUCT( (DT_Thucte!$E$2:$E$1007)* (DT_Thucte!$A$2:$A$1007="ITO")* (YEAR(DT_Thucte!$F$2:$F$1007)=$C$20)* (MONTH(DT_Thucte!$F$2:$F$1007)=VALUE(RIGHT($B30,2))) ) -> 866631085 | F30: =KH_Nam_Hieuchinh!D29 -> 831000000 | G30: =SUMPRODUCT( ('KH DT_HD da ky'!$E$2:$E$993)* ('KH DT_HD da ky'!$A$2:$A$993="UNI")* (YEAR('KH DT_HD da ky'!$F$2:$F$993)=$C$20)* (MONTH('KH DT_HD da ky'!$F$2:$F$993)=VALUE(RIGHT($B30,2))) ) -> 0 | H30: =KH_Nam_Hieuchinh!H29 -> 0 | I30: =SUMPRODUCT( (DT_Thucte!$E$2:$E$1007)* (DT_Thucte!$A$2:$A$1007="UNI")* (YEAR(DT_Thucte!$F$2:$F$1007)=$C$20)* (MONTH(DT_Thucte!$F$2:$F$1007)=VALUE(RIGHT($B30,2))) ) -> 0 | J30: =KH_Nam_Hieuchinh!E29 -> 900000000 | K30: =SUMPRODUCT( ('KH DT_HD da ky'!$E$2:$E$993)* ('KH DT_HD da ky'!$A$2:$A$993="G2B")* (YEAR('KH DT_HD da ky'!$F$2:$F$993)=$C$20)* (MONTH('KH DT_HD da ky'!$F$2:$F$993)=VALUE(RIGHT($B30,2))) ) -> 235925500 | L30: =KH_Nam_Hieuchinh!I29 -> 0 | M30: =SUMPRODUCT( (DT_Thucte!$E$2:$E$1007)* (DT_Thucte!$A$2:$A$1007="G2B")* (YEAR(DT_Thucte!$F$2:$F$1007)=$C$20)* (MONTH(DT_Thucte!$F$2:$F$1007)=VALUE(RIGHT($B30,2))) ) -> 88500000 | N30: =C30+F30+J30 -> 2681000000 | O30: =G30+K30 -> 235925500 | P30: =D30+H30+L30 -> 0 | Q30: =E30+I30+M30 -> 955131085
A31: 9 | B31: Tháng 09 | C31: =KH_Nam_Hieuchinh!C30 -> 950000000 | D31: =KH_Nam_Hieuchinh!G30 -> 950000000 | E31: =SUMPRODUCT( (DT_Thucte!$E$2:$E$1007)* (DT_Thucte!$A$2:$A$1007="ITO")* (YEAR(DT_Thucte!$F$2:$F$1007)=$C$20)* (MONTH(DT_Thucte!$F$2:$F$1007)=VALUE(RIGHT($B31,2))) ) -> 0 | F31: =KH_Nam_Hieuchinh!D30 -> 725500000 | G31: =SUMPRODUCT( ('KH DT_HD da ky'!$E$2:$E$993)* ('KH DT_HD da ky'!$A$2:$A$993="UNI")* (YEAR('KH DT_HD da ky'!$F$2:$F$993)=$C$20)* (MONTH('KH DT_HD da ky'!$F$2:$F$993)=VALUE(RIGHT($B31,2))) ) -> 0 | H31: =KH_Nam_Hieuchinh!H30 -> 2111910000 | I31: =SUMPRODUCT( (DT_Thucte!$E$2:$E$1007)* (DT_Thucte!$A$2:$A$1007="UNI")* (YEAR(DT_Thucte!$F$2:$F$1007)=$C$20)* (MONTH(DT_Thucte!$F$2:$F$1007)=VALUE(RIGHT($B31,2))) ) -> 143505000 | J31: =KH_Nam_Hieuchinh!E30 -> 800000000 | K31: =SUMPRODUCT( ('KH DT_HD da ky'!$E$2:$E$993)* ('KH DT_HD da ky'!$A$2:$A$993="G2B")* (YEAR('KH DT_HD da ky'!$F$2:$F$993)=$C$20)* (MONTH('KH DT_HD da ky'!$F$2:$F$993)=VALUE(RIGHT($B31,2))) ) -> 0 | L31: =KH_Nam_Hieuchinh!I30 -> 978610000 | M31: =SUMPRODUCT( (DT_Thucte!$E$2:$E$1007)* (DT_Thucte!$A$2:$A$1007="G2B")* (YEAR(DT_Thucte!$F$2:$F$1007)=$C$20)* (MONTH(DT_Thucte!$F$2:$F$1007)=VALUE(RIGHT($B31,2))) ) -> 42000000 | N31: =C31+F31+J31 -> 2475500000 | O31: =G31+K31 -> 0 | P31: =D31+H31+L31 -> 4040520000 | Q31: =E31+I31+M31 -> 185505000 | R31: =SUM(Q29:Q31) -> 4221332690
A32: 10 | B32: Tháng 10 | C32: =KH_Nam_Hieuchinh!C31 -> 950000000 | D32: =KH_Nam_Hieuchinh!G31 -> 950000000 | E32: =SUMPRODUCT( (DT_Thucte!$E$2:$E$1007)* (DT_Thucte!$A$2:$A$1007="ITO")* (YEAR(DT_Thucte!$F$2:$F$1007)=$C$20)* (MONTH(DT_Thucte!$F$2:$F$1007)=VALUE(RIGHT($B32,2))) ) -> 0 | F32: =KH_Nam_Hieuchinh!D31 -> 682500000 | G32: =SUMPRODUCT( ('KH DT_HD da ky'!$E$2:$E$993)* ('KH DT_HD da ky'!$A$2:$A$993="UNI")* (YEAR('KH DT_HD da ky'!$F$2:$F$993)=$C$20)* (MONTH('KH DT_HD da ky'!$F$2:$F$993)=VALUE(RIGHT($B32,2))) ) -> 26000000 | H32: =KH_Nam_Hieuchinh!H31 -> 2254800000 | I32: =SUMPRODUCT( (DT_Thucte!$E$2:$E$1007)* (DT_Thucte!$A$2:$A$1007="UNI")* (YEAR(DT_Thucte!$F$2:$F$1007)=$C$20)* (MONTH(DT_Thucte!$F$2:$F$1007)=VALUE(RIGHT($B32,2))) ) -> 0 | J32: =KH_Nam_Hieuchinh!E31 -> 600000000 | K32: =SUMPRODUCT( ('KH DT_HD da ky'!$E$2:$E$993)* ('KH DT_HD da ky'!$A$2:$A$993="G2B")* (YEAR('KH DT_HD da ky'!$F$2:$F$993)=$C$20)* (MONTH('KH DT_HD da ky'!$F$2:$F$993)=VALUE(RIGHT($B32,2))) ) -> 16500000 | L32: =KH_Nam_Hieuchinh!I31 -> 2237370000 | M32: =SUMPRODUCT( (DT_Thucte!$E$2:$E$1007)* (DT_Thucte!$A$2:$A$1007="G2B")* (YEAR(DT_Thucte!$F$2:$F$1007)=$C$20)* (MONTH(DT_Thucte!$F$2:$F$1007)=VALUE(RIGHT($B32,2))) ) -> 0 | N32: =C32+F32+J32 -> 2232500000 | O32: =G32+K32 -> 42500000 | P32: =D32+H32+L32 -> 5442170000 | Q32: =E32+I32+M32 -> 0
A33: 11 | B33: Tháng 11 | C33: =KH_Nam_Hieuchinh!C32 -> 950000000 | D33: =KH_Nam_Hieuchinh!G32 -> 950000000 | E33: =SUMPRODUCT( (DT_Thucte!$E$2:$E$1007)* (DT_Thucte!$A$2:$A$1007="ITO")* (YEAR(DT_Thucte!$F$2:$F$1007)=$C$20)* (MONTH(DT_Thucte!$F$2:$F$1007)=VALUE(RIGHT($B33,2))) ) -> 0 | F33: =KH_Nam_Hieuchinh!D32 -> 700000000 | G33: =SUMPRODUCT( ('KH DT_HD da ky'!$E$2:$E$993)* ('KH DT_HD da ky'!$A$2:$A$993="UNI")* (YEAR('KH DT_HD da ky'!$F$2:$F$993)=$C$20)* (MONTH('KH DT_HD da ky'!$F$2:$F$993)=VALUE(RIGHT($B33,2))) ) -> 0 | H33: =KH_Nam_Hieuchinh!H32 -> 437800000 | I33: =SUMPRODUCT( (DT_Thucte!$E$2:$E$1007)* (DT_Thucte!$A$2:$A$1007="UNI")* (YEAR(DT_Thucte!$F$2:$F$1007)=$C$20)* (MONTH(DT_Thucte!$F$2:$F$1007)=VALUE(RIGHT($B33,2))) ) -> 0 | J33: =KH_Nam_Hieuchinh!E32 -> 970000000 | K33: =SUMPRODUCT( ('KH DT_HD da ky'!$E$2:$E$993)* ('KH DT_HD da ky'!$A$2:$A$993="G2B")* (YEAR('KH DT_HD da ky'!$F$2:$F$993)=$C$20)* (MONTH('KH DT_HD da ky'!$F$2:$F$993)=VALUE(RIGHT($B33,2))) ) -> 168798600 | L33: =KH_Nam_Hieuchinh!I32 -> 1203500000 | M33: =SUMPRODUCT( (DT_Thucte!$E$2:$E$1007)* (DT_Thucte!$A$2:$A$1007="G2B")* (YEAR(DT_Thucte!$F$2:$F$1007)=$C$20)* (MONTH(DT_Thucte!$F$2:$F$1007)=VALUE(RIGHT($B33,2))) ) -> 0 | N33: =C33+F33+J33 -> 2620000000 | O33: =G33+K33 -> 168798600 | P33: =D33+H33+L33 -> 2591300000 | Q33: =E33+I33+M33 -> 0
A34: 12 | B34: Tháng 12 | C34: =KH_Nam_Hieuchinh!C33 -> 950000000 | D34: =KH_Nam_Hieuchinh!G33 -> 950000000 | E34: =SUMPRODUCT( (DT_Thucte!$E$2:$E$1007)* (DT_Thucte!$A$2:$A$1007="ITO")* (YEAR(DT_Thucte!$F$2:$F$1007)=$C$20)* (MONTH(DT_Thucte!$F$2:$F$1007)=VALUE(RIGHT($B34,2))) ) -> 0 | F34: =KH_Nam_Hieuchinh!D33 -> 1645000000 | G34: =SUMPRODUCT( ('KH DT_HD da ky'!$E$2:$E$993)* ('KH DT_HD da ky'!$A$2:$A$993="UNI")* (YEAR('KH DT_HD da ky'!$F$2:$F$993)=$C$20)* (MONTH('KH DT_HD da ky'!$F$2:$F$993)=VALUE(RIGHT($B34,2))) ) -> 756370588 | H34: =KH_Nam_Hieuchinh!H33 -> 9027526000 | I34: =SUMPRODUCT( (DT_Thucte!$E$2:$E$1007)* (DT_Thucte!$A$2:$A$1007="UNI")* (YEAR(DT_Thucte!$F$2:$F$1007)=$C$20)* (MONTH(DT_Thucte!$F$2:$F$1007)=VALUE(RIGHT($B34,2))) ) -> 0 | J34: =KH_Nam_Hieuchinh!E33 -> 1500000000 | K34: =SUMPRODUCT( ('KH DT_HD da ky'!$E$2:$E$993)* ('KH DT_HD da ky'!$A$2:$A$993="G2B")* (YEAR('KH DT_HD da ky'!$F$2:$F$993)=$C$20)* (MONTH('KH DT_HD da ky'!$F$2:$F$993)=VALUE(RIGHT($B34,2))) ) -> 102500000 | L34: =KH_Nam_Hieuchinh!I33 -> 2520000000 | M34: =SUMPRODUCT( (DT_Thucte!$E$2:$E$1007)* (DT_Thucte!$A$2:$A$1007="G2B")* (YEAR(DT_Thucte!$F$2:$F$1007)=$C$20)* (MONTH(DT_Thucte!$F$2:$F$1007)=VALUE(RIGHT($B34,2))) ) -> 0 | N34: =C34+F34+J34 -> 4095000000 | O34: =G34+K34 -> 858870588 | P34: =D34+H34+L34 -> 12497526000 | Q34: =E34+I34+M34 -> 0 | R34: =SUM(Q32:Q34) -> 0
B35: Đến hiện tại | C35: =SUM(C23:C34) -> 11400000000 | D35: =SUM(D23:D34) -> 3800000000 | E35: =SUM(E23:E34) -> 7467087080 | F35: =SUM(F23:F34) -> 9300000000 | G35: =SUM(G23:G34) -> 782370588 | H35: =SUM(H23:H34) -> 13832036000 | I35: =SUM(I23:I34) -> 4924423600 | J35: =SUM(J23:J34) -> 9300000000 | ... M35: =SUM(M23:M34) -> 2710468311 | N35: =C35+F35+J35 -> 30000000000 | O35: =G35+K35 -> 1306094688 | P35: =D35+H35+L35 -> 24571516000 | Q35: =E35+I35+M35 -> 15101978991
B36: Tỷ lệ | E36: =E35/C35 -> 0.65500764 | I36: =I35/F35 -> 0.52950791 | M36: =M35/J35 -> 0.29144821 | Q36: =Q35/N35 -> 0.5033993
P37: G2B+UNI | Q37: =I35+M35 -> 7634891911
N40: =SUM(M8:M10) -> 0 | O40: =SUM(O26:O28) -> 0 | P40: =SUM(P26:P28) -> 0
O42: =O40+P40 -> 0

Sheet TH theo khach hang
D1: =D4+D6+D107+D208 -> 0 | E1: =E4+E6+E107+E208 -> 0 | H1: =SUMIF($C$4:$C$308,"X",$H$4:$H$308) -> 0 | I1: =SUMIF($C$4:$C$308,"X",$I$4:$I$308) -> 0
A2: Mã số | B2: Tên sản phẩm, khách hàng | C2: Bảo trì | E2: Kế hoạch đầu năm | J2: Thực tế
D3: Hợp đồng | E3: Doanh thu | F3: Là DT từ dự án | G3: Thời gian HĐ | H3: Hợp đồng | I3: Doanh thu | J3: Ghi doanh thu | K3: Doanh thu còn lại | L3: Công nợ | M3: Thời gian DT
A4: NHÓM ITO | D4: =D5 -> 0 | E4: =E5 -> 0
A5: ITO01 | B5: Hợp đồng Outsource | E5: =D5 -> 0 | H5: =VLOOKUP(A5,'Thuc te theo thang'!$A$4:$I$309,8,FALSE()) -> 0 | I5: =VLOOKUP(A5,'Thuc te theo thang'!$A$4:$I$309,9,FALSE()) -> 0 | K5: =H5-I5-J5 -> 0
A6: NHÓM UNI | D6: =SUM(D7:D106) -> 0 | E6: =SUM(E7:E106) -> 0 | H6: =SUMIF($C$7:$C$106,"x",H7:H106) -> 0 | I6: =SUMIF($C$7:$C$106,"x",I7:I106) -> 0 | K6: =SUM(K7:K106) -> 0
A7: UNI01 | H7: =VLOOKUP(A7,'Thuc te theo thang'!$A$4:$I$309,8,FALSE()) -> 0 | I7: =VLOOKUP(A7,'Thuc te theo thang'!$A$4:$I$309,9,FALSE()) -> 0 | K7: =H7-I7-J7 -> 0
A8: UNI02 | H8: =VLOOKUP(A8,'Thuc te theo thang'!$A$4:$I$309,8,FALSE()) -> 0 | I8: =VLOOKUP(A8,'Thuc te theo thang'!$A$4:$I$309,9,FALSE()) -> 0 | K8: =H8-I8-J8 -> 0
A9: UNI03 | H9: =VLOOKUP(A9,'Thuc te theo thang'!$A$4:$I$309,8,FALSE()) -> 0 | I9: =VLOOKUP(A9,'Thuc te theo thang'!$A$4:$I$309,9,FALSE()) -> 0 | K9: =H9-I9-J9 -> 0
A10: UNI04 | H10: =VLOOKUP(A10,'Thuc te theo thang'!$A$4:$I$309,8,FALSE()) -> 0 | I10: =VLOOKUP(A10,'Thuc te theo thang'!$A$4:$I$309,9,FALSE()) -> 0 | K10: =H10-I10-J10 -> 0
A11: UNI05 | H11: =VLOOKUP(A11,'Thuc te theo thang'!$A$4:$I$309,8,FALSE()) -> 0 | I11: =VLOOKUP(A11,'Thuc te theo thang'!$A$4:$I$309,9,FALSE()) -> 0 | K11: =H11-I11-J11 -> 0
A12: UNI06 | H12: =VLOOKUP(A12,'Thuc te theo thang'!$A$4:$I$309,8,FALSE()) -> 0 | I12: =VLOOKUP(A12,'Thuc te theo thang'!$A$4:$I$309,9,FALSE()) -> 0 | K12: =H12-I12-J12 -> 0
A13: UNI07 | H13: =VLOOKUP(A13,'Thuc te theo thang'!$A$4:$I$309,8,FALSE()) -> 0 | I13: =VLOOKUP(A13,'Thuc te theo thang'!$A$4:$I$309,9,FALSE()) -> 0 | K13: =H13-I13-J13 -> 0
A14: UNI08 | H14: =VLOOKUP(A14,'Thuc te theo thang'!$A$4:$I$309,8,FALSE()) -> 0 | I14: =VLOOKUP(A14,'Thuc te theo thang'!$A$4:$I$309,9,FALSE()) -> 0 | K14: =H14-I14-J14 -> 0
A15: UNI09 | H15: =VLOOKUP(A15,'Thuc te theo thang'!$A$4:$I$309,8,FALSE()) -> 0 | I15: =VLOOKUP(A15,'Thuc te theo thang'!$A$4:$I$309,9,FALSE()) -> 0 | K15: =H15-I15-J15 -> 0
A16: UNI10 | H16: =VLOOKUP(A16,'Thuc te theo thang'!$A$4:$I$309,8,FALSE()) -> 0 | I16: =VLOOKUP(A16,'Thuc te theo thang'!$A$4:$I$309,9,FALSE()) -> 0 | K16: =H16-I16-J16 -> 0
A17: UNI11 | H17: =VLOOKUP(A17,'Thuc te theo thang'!$A$4:$I$309,8,FALSE()) -> 0 | I17: =VLOOKUP(A17,'Thuc te theo thang'!$A$4:$I$309,9,FALSE()) -> 0 | K17: =H17-I17-J17 -> 0
